ERROR:sqlalchemy.pool.impl.NullPool:Exception during reset or similar
Traceback (most recent call last):
  File "C:\Users\tiago\AppData\Local\Programs\Python\Python312\Lib\site-packages\sqlalchemy\pool\base.py", line 753, in _finalize_fairy
    fairy._reset(pool)
  File "C:\Users\tiago\AppData\Local\Programs\Python\Python312\Lib\site-packages\sqlalchemy\pool\base.py", line 1004, in _reset
    pool._dialect.do_rollback(self)
  File "C:\Users\tiago\AppData\Local\Programs\Python\Python312\Lib\site-packages\sqlalchemy\engine\default.py", line 683, in do_rollback
    dbapi_connection.rollback()
sqlite3.ProgrammingError: SQLite objects created in a thread can only be used in that same thread. The object was created in thread id 29992 and this is thread id 57920.
ERROR:sqlalchemy.pool.impl.NullPool:Exception closing connection <sqlite3.Connection object at 0x0000028C73D631F0>
Traceback (most recent call last):
  File "C:\Users\tiago\AppData\Local\Programs\Python\Python312\Lib\site-packages\sqlalchemy\pool\base.py", line 753, in _finalize_fairy
    fairy._reset(pool)
  File "C:\Users\tiago\AppData\Local\Programs\Python\Python312\Lib\site-packages\sqlalchemy\pool\base.py", line 1004, in _reset
    pool._dialect.do_rollback(self)
  File "C:\Users\tiago\AppData\Local\Programs\Python\Python312\Lib\site-packages\sqlalchemy\engine\default.py", line 683, in do_rollback
    dbapi_connection.rollback()
sqlite3.ProgrammingError: SQLite objects created in a thread can only be used in that same thread. The object was created in thread id 29992 and this is thread id 57920.

During handling of the above exception, another exception occurred:

Traceback (most recent call last):
  File "C:\Users\tiago\AppData\Local\Programs\Python\Python312\Lib\site-packages\sqlalchemy\pool\base.py", line 255, in _close_connection
    self._dialect.do_terminate(connection)
  File "C:\Users\tiago\AppData\Local\Programs\Python\Python312\Lib\site-packages\sqlalchemy\engine\default.py", line 689, in do_terminate
    self.do_close(dbapi_connection)
  File "C:\Users\tiago\AppData\Local\Programs\Python\Python312\Lib\site-packages\sqlalchemy\engine\default.py", line 692, in do_close
    dbapi_connection.close()
sqlite3.ProgrammingError: SQLite objects created in a thread can only be used in that same thread. The object was created in thread id 29992 and this is thread id 57920.
ERROR:sqlalchemy.pool.impl.NullPool:Exception during reset or similar
Traceback (most recent call last):
  File "C:\Users\tiago\AppData\Local\Programs\Python\Python312\Lib\site-packages\sqlalchemy\pool\base.py", line 753, in _finalize_fairy
    fairy._reset(pool)
  File "C:\Users\tiago\AppData\Local\Programs\Python\Python312\Lib\site-packages\sqlalchemy\pool\base.py", line 1004, in _reset
    pool._dialect.do_rollback(self)
  File "C:\Users\tiago\AppData\Local\Programs\Python\Python312\Lib\site-packages\sqlalchemy\engine\default.py", line 683, in do_rollback
    dbapi_connection.rollback()
sqlite3.ProgrammingError: SQLite objects created in a thread can only be used in that same thread. The object was created in thread id 49836 and this is thread id 57920.
ERROR:sqlalchemy.pool.impl.NullPool:Exception closing connection <sqlite3.Connection object at 0x0000028C73D624D0>
Traceback (most recent call last):
  File "C:\Users\tiago\AppData\Local\Programs\Python\Python312\Lib\site-packages\sqlalchemy\pool\base.py", line 753, in _finalize_fairy
    fairy._reset(pool)
  File "C:\Users\tiago\AppData\Local\Programs\Python\Python312\Lib\site-packages\sqlalchemy\pool\base.py", line 1004, in _reset
    pool._dialect.do_rollback(self)
  File "C:\Users\tiago\AppData\Local\Programs\Python\Python312\Lib\site-packages\sqlalchemy\engine\default.py", line 683, in do_rollback
    dbapi_connection.rollback()
sqlite3.ProgrammingError: SQLite objects created in a thread can only be used in that same thread. The object was created in thread id 49836 and this is thread id 57920.

During handling of the above exception, another exception occurred:

Traceback (most recent call last):
  File "C:\Users\tiago\AppData\Local\Programs\Python\Python312\Lib\site-packages\sqlalchemy\pool\base.py", line 255, in _close_connection
    self._dialect.do_terminate(connection)
  File "C:\Users\tiago\AppData\Local\Programs\Python\Python312\Lib\site-packages\sqlalchemy\engine\default.py", line 689, in do_terminate
    self.do_close(dbapi_connection)
  File "C:\Users\tiago\AppData\Local\Programs\Python\Python312\Lib\site-packages\sqlalchemy\engine\default.py", line 692, in do_close
    dbapi_connection.close()
sqlite3.ProgrammingError: SQLite objects created in a thread can only be used in that same thread. The object was created in thread id 49836 and this is thread id 57920.
ERROR:sqlalchemy.pool.impl.NullPool:Exception during reset or similar
Traceback (most recent call last):
  File "C:\Users\tiago\AppData\Local\Programs\Python\Python312\Lib\site-packages\sqlalchemy\pool\base.py", line 753, in _finalize_fairy
    fairy._reset(pool)
  File "C:\Users\tiago\AppData\Local\Programs\Python\Python312\Lib\site-packages\sqlalchemy\pool\base.py", line 1004, in _reset
    pool._dialect.do_rollback(self)
  File "C:\Users\tiago\AppData\Local\Programs\Python\Python312\Lib\site-packages\sqlalchemy\engine\default.py", line 683, in do_rollback
    dbapi_connection.rollback()
sqlite3.ProgrammingError: SQLite objects created in a thread can only be used in that same thread. The object was created in thread id 57028 and this is thread id 57920.
ERROR:sqlalchemy.pool.impl.NullPool:Exception closing connection <sqlite3.Connection object at 0x0000028C73EEB790>
Traceback (most recent call last):
  File "C:\Users\tiago\AppData\Local\Programs\Python\Python312\Lib\site-packages\sqlalchemy\pool\base.py", line 753, in _finalize_fairy
    fairy._reset(pool)
  File "C:\Users\tiago\AppData\Local\Programs\Python\Python312\Lib\site-packages\sqlalchemy\pool\base.py", line 1004, in _reset
    pool._dialect.do_rollback(self)
  File "C:\Users\tiago\AppData\Local\Programs\Python\Python312\Lib\site-packages\sqlalchemy\engine\default.py", line 683, in do_rollback
    dbapi_connection.rollback()
sqlite3.ProgrammingError: SQLite objects created in a thread can only be used in that same thread. The object was created in thread id 57028 and this is thread id 57920.

During handling of the above exception, another exception occurred:

Traceback (most recent call last):
  File "C:\Users\tiago\AppData\Local\Programs\Python\Python312\Lib\site-packages\sqlalchemy\pool\base.py", line 255, in _close_connection
    self._dialect.do_terminate(connection)
  File "C:\Users\tiago\AppData\Local\Programs\Python\Python312\Lib\site-packages\sqlalchemy\engine\default.py", line 689, in do_terminate
    self.do_close(dbapi_connection)
  File "C:\Users\tiago\AppData\Local\Programs\Python\Python312\Lib\site-packages\sqlalchemy\engine\default.py", line 692, in do_close
    dbapi_connection.close()
sqlite3.ProgrammingError: SQLite objects created in a thread can only be used in that same thread. The object was created in thread id 57028 and this is thread id 57920.
ERROR:sqlalchemy.pool.impl.NullPool:Exception during reset or similar
Traceback (most recent call last):
  File "C:\Users\tiago\AppData\Local\Programs\Python\Python312\Lib\site-packages\sqlalchemy\pool\base.py", line 753, in _finalize_fairy
    fairy._reset(pool)
  File "C:\Users\tiago\AppData\Local\Programs\Python\Python312\Lib\site-packages\sqlalchemy\pool\base.py", line 1004, in _reset
    pool._dialect.do_rollback(self)
  File "C:\Users\tiago\AppData\Local\Programs\Python\Python312\Lib\site-packages\sqlalchemy\engine\default.py", line 683, in do_rollback
    dbapi_connection.rollback()
sqlite3.ProgrammingError: SQLite objects created in a thread can only be used in that same thread. The object was created in thread id 47100 and this is thread id 57920.
ERROR:sqlalchemy.pool.impl.NullPool:Exception closing connection <sqlite3.Connection object at 0x0000028C73EEA890>
Traceback (most recent call last):
  File "C:\Users\tiago\AppData\Local\Programs\Python\Python312\Lib\site-packages\sqlalchemy\pool\base.py", line 753, in _finalize_fairy
    fairy._reset(pool)
  File "C:\Users\tiago\AppData\Local\Programs\Python\Python312\Lib\site-packages\sqlalchemy\pool\base.py", line 1004, in _reset
    pool._dialect.do_rollback(self)
  File "C:\Users\tiago\AppData\Local\Programs\Python\Python312\Lib\site-packages\sqlalchemy\engine\default.py", line 683, in do_rollback
    dbapi_connection.rollback()
sqlite3.ProgrammingError: SQLite objects created in a thread can only be used in that same thread. The object was created in thread id 47100 and this is thread id 57920.

During handling of the above exception, another exception occurred:

Traceback (most recent call last):
  File "C:\Users\tiago\AppData\Local\Programs\Python\Python312\Lib\site-packages\sqlalchemy\pool\base.py", line 255, in _close_connection
    self._dialect.do_terminate(connection)
  File "C:\Users\tiago\AppData\Local\Programs\Python\Python312\Lib\site-packages\sqlalchemy\engine\default.py", line 689, in do_terminate
    self.do_close(dbapi_connection)
  File "C:\Users\tiago\AppData\Local\Programs\Python\Python312\Lib\site-packages\sqlalchemy\engine\default.py", line 692, in do_close
    dbapi_connection.close()
sqlite3.ProgrammingError: SQLite objects created in a thread can only be used in that same thread. The object was created in thread id 47100 and this is thread id 57920.
ERROR:sqlalchemy.pool.impl.NullPool:Exception during reset or similar
Traceback (most recent call last):
  File "C:\Users\tiago\AppData\Local\Programs\Python\Python312\Lib\site-packages\sqlalchemy\pool\base.py", line 753, in _finalize_fairy
    fairy._reset(pool)
  File "C:\Users\tiago\AppData\Local\Programs\Python\Python312\Lib\site-packages\sqlalchemy\pool\base.py", line 1004, in _reset
    pool._dialect.do_rollback(self)
  File "C:\Users\tiago\AppData\Local\Programs\Python\Python312\Lib\site-packages\sqlalchemy\engine\default.py", line 683, in do_rollback
    dbapi_connection.rollback()
sqlite3.ProgrammingError: SQLite objects created in a thread can only be used in that same thread. The object was created in thread id 58872 and this is thread id 57920.
ERROR:sqlalchemy.pool.impl.NullPool:Exception closing connection <sqlite3.Connection object at 0x0000028C73EEAD40>
Traceback (most recent call last):
  File "C:\Users\tiago\AppData\Local\Programs\Python\Python312\Lib\site-packages\sqlalchemy\pool\base.py", line 753, in _finalize_fairy
    fairy._reset(pool)
  File "C:\Users\tiago\AppData\Local\Programs\Python\Python312\Lib\site-packages\sqlalchemy\pool\base.py", line 1004, in _reset
    pool._dialect.do_rollback(self)
  File "C:\Users\tiago\AppData\Local\Programs\Python\Python312\Lib\site-packages\sqlalchemy\engine\default.py", line 683, in do_rollback
    dbapi_connection.rollback()
sqlite3.ProgrammingError: SQLite objects created in a thread can only be used in that same thread. The object was created in thread id 58872 and this is thread id 57920.

During handling of the above exception, another exception occurred:

Traceback (most recent call last):
  File "C:\Users\tiago\AppData\Local\Programs\Python\Python312\Lib\site-packages\sqlalchemy\pool\base.py", line 255, in _close_connection
    self._dialect.do_terminate(connection)
  File "C:\Users\tiago\AppData\Local\Programs\Python\Python312\Lib\site-packages\sqlalchemy\engine\default.py", line 689, in do_terminate
    self.do_close(dbapi_connection)
  File "C:\Users\tiago\AppData\Local\Programs\Python\Python312\Lib\site-packages\sqlalchemy\engine\default.py", line 692, in do_close
    dbapi_connection.close()
sqlite3.ProgrammingError: SQLite objects created in a thread can only be used in that same thread. The object was created in thread id 58872 and this is thread id 57920.
INFO:werkzeug:[31m[1mWARNING: This is a development server. Do not use it in a production deployment. Use a production WSGI server instead.[0m
 * Running on http://127.0.0.1:5000
INFO:werkzeug:[33mPress CTRL+C to quit[0m
DEBUG:root:Consulta todos os eventos
INFO:werkzeug:127.0.0.1 - - [17/Apr/2024 09:33:25] "GET /evento HTTP/1.1" 200 -
DEBUG:root:Consulta todos os eventos
INFO:werkzeug:127.0.0.1 - - [17/Apr/2024 09:33:26] "GET /eventoporid?id=2 HTTP/1.1" 200 -
DEBUG:root:Consulta todos os responsavels
DEBUG:root:Consulta todas as salas
INFO:werkzeug:127.0.0.1 - - [17/Apr/2024 09:33:27] "GET /responsavel?eventoid=2 HTTP/1.1" 200 -
INFO:werkzeug:127.0.0.1 - - [17/Apr/2024 09:33:27] "GET /sala HTTP/1.1" 200 -
DEBUG:root:Consulta todos os centrodeinteresses
DEBUG:root:Consulta todos os participantes
INFO:werkzeug:127.0.0.1 - - [17/Apr/2024 09:33:27] "GET /centrodeinteresse?eventoId=2 HTTP/1.1" 200 -
INFO:werkzeug:127.0.0.1 - - [17/Apr/2024 09:33:27] "GET /participante?eventoId=2 HTTP/1.1" 200 -
DEBUG:root:Consulta todos os responsavels
DEBUG:root:Consulta todos os centrodeinteresses
INFO:werkzeug:127.0.0.1 - - [17/Apr/2024 09:33:27] "GET /responsavel?eventoid=2 HTTP/1.1" 200 -
INFO:werkzeug:127.0.0.1 - - [17/Apr/2024 09:33:27] "GET /centrodeinteresse?eventoId=2 HTTP/1.1" 200 -
DEBUG:root:Consulta todos os centrodeinteresses
INFO:werkzeug:127.0.0.1 - - [17/Apr/2024 09:33:27] "GET /centrodeinteresse?eventoId=2 HTTP/1.1" 200 -
ERROR:sqlalchemy.pool.impl.NullPool:Exception during reset or similar
Traceback (most recent call last):
  File "C:\Users\tiago\AppData\Local\Programs\Python\Python312\Lib\site-packages\sqlalchemy\pool\base.py", line 753, in _finalize_fairy
    fairy._reset(pool)
  File "C:\Users\tiago\AppData\Local\Programs\Python\Python312\Lib\site-packages\sqlalchemy\pool\base.py", line 1004, in _reset
    pool._dialect.do_rollback(self)
  File "C:\Users\tiago\AppData\Local\Programs\Python\Python312\Lib\site-packages\sqlalchemy\engine\default.py", line 683, in do_rollback
    dbapi_connection.rollback()
sqlite3.ProgrammingError: SQLite objects created in a thread can only be used in that same thread. The object was created in thread id 48680 and this is thread id 57952.
ERROR:sqlalchemy.pool.impl.NullPool:Exception closing connection <sqlite3.Connection object at 0x0000022D887DCE50>
Traceback (most recent call last):
  File "C:\Users\tiago\AppData\Local\Programs\Python\Python312\Lib\site-packages\sqlalchemy\pool\base.py", line 753, in _finalize_fairy
    fairy._reset(pool)
  File "C:\Users\tiago\AppData\Local\Programs\Python\Python312\Lib\site-packages\sqlalchemy\pool\base.py", line 1004, in _reset
    pool._dialect.do_rollback(self)
  File "C:\Users\tiago\AppData\Local\Programs\Python\Python312\Lib\site-packages\sqlalchemy\engine\default.py", line 683, in do_rollback
    dbapi_connection.rollback()
sqlite3.ProgrammingError: SQLite objects created in a thread can only be used in that same thread. The object was created in thread id 48680 and this is thread id 57952.

During handling of the above exception, another exception occurred:

Traceback (most recent call last):
  File "C:\Users\tiago\AppData\Local\Programs\Python\Python312\Lib\site-packages\sqlalchemy\pool\base.py", line 255, in _close_connection
    self._dialect.do_terminate(connection)
  File "C:\Users\tiago\AppData\Local\Programs\Python\Python312\Lib\site-packages\sqlalchemy\engine\default.py", line 689, in do_terminate
    self.do_close(dbapi_connection)
  File "C:\Users\tiago\AppData\Local\Programs\Python\Python312\Lib\site-packages\sqlalchemy\engine\default.py", line 692, in do_close
    dbapi_connection.close()
sqlite3.ProgrammingError: SQLite objects created in a thread can only be used in that same thread. The object was created in thread id 48680 and this is thread id 57952.
ERROR:sqlalchemy.pool.impl.NullPool:Exception during reset or similar
Traceback (most recent call last):
  File "C:\Users\tiago\AppData\Local\Programs\Python\Python312\Lib\site-packages\sqlalchemy\pool\base.py", line 753, in _finalize_fairy
    fairy._reset(pool)
  File "C:\Users\tiago\AppData\Local\Programs\Python\Python312\Lib\site-packages\sqlalchemy\pool\base.py", line 1004, in _reset
    pool._dialect.do_rollback(self)
  File "C:\Users\tiago\AppData\Local\Programs\Python\Python312\Lib\site-packages\sqlalchemy\engine\default.py", line 683, in do_rollback
    dbapi_connection.rollback()
sqlite3.ProgrammingError: SQLite objects created in a thread can only be used in that same thread. The object was created in thread id 5960 and this is thread id 57952.
ERROR:sqlalchemy.pool.impl.NullPool:Exception closing connection <sqlite3.Connection object at 0x0000022D889B5990>
Traceback (most recent call last):
  File "C:\Users\tiago\AppData\Local\Programs\Python\Python312\Lib\site-packages\sqlalchemy\pool\base.py", line 753, in _finalize_fairy
    fairy._reset(pool)
  File "C:\Users\tiago\AppData\Local\Programs\Python\Python312\Lib\site-packages\sqlalchemy\pool\base.py", line 1004, in _reset
    pool._dialect.do_rollback(self)
  File "C:\Users\tiago\AppData\Local\Programs\Python\Python312\Lib\site-packages\sqlalchemy\engine\default.py", line 683, in do_rollback
    dbapi_connection.rollback()
sqlite3.ProgrammingError: SQLite objects created in a thread can only be used in that same thread. The object was created in thread id 5960 and this is thread id 57952.

During handling of the above exception, another exception occurred:

Traceback (most recent call last):
  File "C:\Users\tiago\AppData\Local\Programs\Python\Python312\Lib\site-packages\sqlalchemy\pool\base.py", line 255, in _close_connection
    self._dialect.do_terminate(connection)
  File "C:\Users\tiago\AppData\Local\Programs\Python\Python312\Lib\site-packages\sqlalchemy\engine\default.py", line 689, in do_terminate
    self.do_close(dbapi_connection)
  File "C:\Users\tiago\AppData\Local\Programs\Python\Python312\Lib\site-packages\sqlalchemy\engine\default.py", line 692, in do_close
    dbapi_connection.close()
sqlite3.ProgrammingError: SQLite objects created in a thread can only be used in that same thread. The object was created in thread id 5960 and this is thread id 57952.
ERROR:sqlalchemy.pool.impl.NullPool:Exception during reset or similar
Traceback (most recent call last):
  File "C:\Users\tiago\AppData\Local\Programs\Python\Python312\Lib\site-packages\sqlalchemy\pool\base.py", line 753, in _finalize_fairy
    fairy._reset(pool)
  File "C:\Users\tiago\AppData\Local\Programs\Python\Python312\Lib\site-packages\sqlalchemy\pool\base.py", line 1004, in _reset
    pool._dialect.do_rollback(self)
  File "C:\Users\tiago\AppData\Local\Programs\Python\Python312\Lib\site-packages\sqlalchemy\engine\default.py", line 683, in do_rollback
    dbapi_connection.rollback()
sqlite3.ProgrammingError: SQLite objects created in a thread can only be used in that same thread. The object was created in thread id 58924 and this is thread id 57952.
ERROR:sqlalchemy.pool.impl.NullPool:Exception closing connection <sqlite3.Connection object at 0x0000022D888324D0>
Traceback (most recent call last):
  File "C:\Users\tiago\AppData\Local\Programs\Python\Python312\Lib\site-packages\sqlalchemy\pool\base.py", line 753, in _finalize_fairy
    fairy._reset(pool)
  File "C:\Users\tiago\AppData\Local\Programs\Python\Python312\Lib\site-packages\sqlalchemy\pool\base.py", line 1004, in _reset
    pool._dialect.do_rollback(self)
  File "C:\Users\tiago\AppData\Local\Programs\Python\Python312\Lib\site-packages\sqlalchemy\engine\default.py", line 683, in do_rollback
    dbapi_connection.rollback()
sqlite3.ProgrammingError: SQLite objects created in a thread can only be used in that same thread. The object was created in thread id 58924 and this is thread id 57952.

During handling of the above exception, another exception occurred:

Traceback (most recent call last):
  File "C:\Users\tiago\AppData\Local\Programs\Python\Python312\Lib\site-packages\sqlalchemy\pool\base.py", line 255, in _close_connection
    self._dialect.do_terminate(connection)
  File "C:\Users\tiago\AppData\Local\Programs\Python\Python312\Lib\site-packages\sqlalchemy\engine\default.py", line 689, in do_terminate
    self.do_close(dbapi_connection)
  File "C:\Users\tiago\AppData\Local\Programs\Python\Python312\Lib\site-packages\sqlalchemy\engine\default.py", line 692, in do_close
    dbapi_connection.close()
sqlite3.ProgrammingError: SQLite objects created in a thread can only be used in that same thread. The object was created in thread id 58924 and this is thread id 57952.
DEBUG:root:Consulta todos os eventos
INFO:werkzeug:127.0.0.1 - - [17/Apr/2024 09:33:28] "GET /eventoporid?id=2 HTTP/1.1" 200 -
DEBUG:root:Consulta todos os responsavels
DEBUG:root:Consulta todas as salas
DEBUG:root:Consulta todos os centrodeinteresses
DEBUG:root:Consulta todos os participantes
ERROR:sqlalchemy.pool.impl.NullPool:Exception during reset or similar
Traceback (most recent call last):
  File "C:\Users\tiago\AppData\Local\Programs\Python\Python312\Lib\site-packages\sqlalchemy\pool\base.py", line 753, in _finalize_fairy
    fairy._reset(pool)
  File "C:\Users\tiago\AppData\Local\Programs\Python\Python312\Lib\site-packages\sqlalchemy\pool\base.py", line 1004, in _reset
    pool._dialect.do_rollback(self)
  File "C:\Users\tiago\AppData\Local\Programs\Python\Python312\Lib\site-packages\sqlalchemy\engine\default.py", line 683, in do_rollback
    dbapi_connection.rollback()
sqlite3.ProgrammingError: SQLite objects created in a thread can only be used in that same thread. The object was created in thread id 57952 and this is thread id 58780.
INFO:werkzeug:127.0.0.1 - - [17/Apr/2024 09:33:28] "GET /responsavel?eventoid=2 HTTP/1.1" 200 -
ERROR:sqlalchemy.pool.impl.NullPool:Exception closing connection <sqlite3.Connection object at 0x0000022D88797880>
Traceback (most recent call last):
  File "C:\Users\tiago\AppData\Local\Programs\Python\Python312\Lib\site-packages\sqlalchemy\pool\base.py", line 753, in _finalize_fairy
    fairy._reset(pool)
  File "C:\Users\tiago\AppData\Local\Programs\Python\Python312\Lib\site-packages\sqlalchemy\pool\base.py", line 1004, in _reset
    pool._dialect.do_rollback(self)
  File "C:\Users\tiago\AppData\Local\Programs\Python\Python312\Lib\site-packages\sqlalchemy\engine\default.py", line 683, in do_rollback
    dbapi_connection.rollback()
sqlite3.ProgrammingError: SQLite objects created in a thread can only be used in that same thread. The object was created in thread id 57952 and this is thread id 58780.

During handling of the above exception, another exception occurred:

Traceback (most recent call last):
  File "C:\Users\tiago\AppData\Local\Programs\Python\Python312\Lib\site-packages\sqlalchemy\pool\base.py", line 255, in _close_connection
    self._dialect.do_terminate(connection)
  File "C:\Users\tiago\AppData\Local\Programs\Python\Python312\Lib\site-packages\sqlalchemy\engine\default.py", line 689, in do_terminate
    self.do_close(dbapi_connection)
  File "C:\Users\tiago\AppData\Local\Programs\Python\Python312\Lib\site-packages\sqlalchemy\engine\default.py", line 692, in do_close
    dbapi_connection.close()
sqlite3.ProgrammingError: SQLite objects created in a thread can only be used in that same thread. The object was created in thread id 57952 and this is thread id 58780.
INFO:werkzeug:127.0.0.1 - - [17/Apr/2024 09:33:28] "GET /centrodeinteresse?eventoId=2 HTTP/1.1" 200 -
INFO:werkzeug:127.0.0.1 - - [17/Apr/2024 09:33:28] "GET /participante?eventoId=2 HTTP/1.1" 200 -
INFO:werkzeug:127.0.0.1 - - [17/Apr/2024 09:33:28] "GET /sala HTTP/1.1" 200 -
DEBUG:root:Consulta todos os responsavels
DEBUG:root:Consulta todos os centrodeinteresses
INFO:werkzeug:127.0.0.1 - - [17/Apr/2024 09:33:28] "GET /responsavel?eventoid=2 HTTP/1.1" 200 -
INFO:werkzeug:127.0.0.1 - - [17/Apr/2024 09:33:28] "GET /centrodeinteresse?eventoId=2 HTTP/1.1" 200 -
DEBUG:root:Consulta todos os centrodeinteresses
INFO:werkzeug:127.0.0.1 - - [17/Apr/2024 09:33:29] "GET /centrodeinteresse?eventoId=2 HTTP/1.1" 200 -
ERROR:sqlalchemy.pool.impl.NullPool:Exception during reset or similar
Traceback (most recent call last):
  File "C:\Users\tiago\AppData\Local\Programs\Python\Python312\Lib\site-packages\pydantic\type_adapter.py", line 210, in __init__
    core_schema = _getattr_no_parents(type, '__pydantic_core_schema__')
                  ^^^^^^^^^^^^^^^^^^^^^^^^^^^^^^^^^^^^^^^^^^^^^^^^^^^^^
  File "C:\Users\tiago\AppData\Local\Programs\Python\Python312\Lib\site-packages\pydantic\type_adapter.py", line 98, in _getattr_no_parents
    raise AttributeError(attribute)
AttributeError: __pydantic_core_schema__

During handling of the above exception, another exception occurred:

Traceback (most recent call last):
  File "C:\Users\tiago\AppData\Local\Programs\Python\Python312\Lib\site-packages\sqlalchemy\pool\base.py", line 753, in _finalize_fairy
    fairy._reset(pool)
  File "C:\Users\tiago\AppData\Local\Programs\Python\Python312\Lib\site-packages\sqlalchemy\pool\base.py", line 1004, in _reset
    pool._dialect.do_rollback(self)
  File "C:\Users\tiago\AppData\Local\Programs\Python\Python312\Lib\site-packages\sqlalchemy\engine\default.py", line 683, in do_rollback
    dbapi_connection.rollback()
sqlite3.ProgrammingError: SQLite objects created in a thread can only be used in that same thread. The object was created in thread id 47352 and this is thread id 59340.
ERROR:sqlalchemy.pool.impl.NullPool:Exception closing connection <sqlite3.Connection object at 0x0000022D889B57B0>
Traceback (most recent call last):
  File "C:\Users\tiago\AppData\Local\Programs\Python\Python312\Lib\site-packages\pydantic\type_adapter.py", line 210, in __init__
    core_schema = _getattr_no_parents(type, '__pydantic_core_schema__')
                  ^^^^^^^^^^^^^^^^^^^^^^^^^^^^^^^^^^^^^^^^^^^^^^^^^^^^^
  File "C:\Users\tiago\AppData\Local\Programs\Python\Python312\Lib\site-packages\pydantic\type_adapter.py", line 98, in _getattr_no_parents
    raise AttributeError(attribute)
AttributeError: __pydantic_core_schema__

During handling of the above exception, another exception occurred:

Traceback (most recent call last):
  File "C:\Users\tiago\AppData\Local\Programs\Python\Python312\Lib\site-packages\sqlalchemy\pool\base.py", line 753, in _finalize_fairy
    fairy._reset(pool)
  File "C:\Users\tiago\AppData\Local\Programs\Python\Python312\Lib\site-packages\sqlalchemy\pool\base.py", line 1004, in _reset
    pool._dialect.do_rollback(self)
  File "C:\Users\tiago\AppData\Local\Programs\Python\Python312\Lib\site-packages\sqlalchemy\engine\default.py", line 683, in do_rollback
    dbapi_connection.rollback()
sqlite3.ProgrammingError: SQLite objects created in a thread can only be used in that same thread. The object was created in thread id 47352 and this is thread id 59340.

During handling of the above exception, another exception occurred:

Traceback (most recent call last):
  File "C:\Users\tiago\AppData\Local\Programs\Python\Python312\Lib\site-packages\sqlalchemy\pool\base.py", line 255, in _close_connection
    self._dialect.do_terminate(connection)
  File "C:\Users\tiago\AppData\Local\Programs\Python\Python312\Lib\site-packages\sqlalchemy\engine\default.py", line 689, in do_terminate
    self.do_close(dbapi_connection)
  File "C:\Users\tiago\AppData\Local\Programs\Python\Python312\Lib\site-packages\sqlalchemy\engine\default.py", line 692, in do_close
    dbapi_connection.close()
sqlite3.ProgrammingError: SQLite objects created in a thread can only be used in that same thread. The object was created in thread id 47352 and this is thread id 59340.
ERROR:sqlalchemy.pool.impl.NullPool:Exception during reset or similar
Traceback (most recent call last):
  File "C:\Users\tiago\AppData\Local\Programs\Python\Python312\Lib\site-packages\pydantic\type_adapter.py", line 210, in __init__
    core_schema = _getattr_no_parents(type, '__pydantic_core_schema__')
                  ^^^^^^^^^^^^^^^^^^^^^^^^^^^^^^^^^^^^^^^^^^^^^^^^^^^^^
  File "C:\Users\tiago\AppData\Local\Programs\Python\Python312\Lib\site-packages\pydantic\type_adapter.py", line 98, in _getattr_no_parents
    raise AttributeError(attribute)
AttributeError: __pydantic_core_schema__

During handling of the above exception, another exception occurred:

Traceback (most recent call last):
  File "C:\Users\tiago\AppData\Local\Programs\Python\Python312\Lib\site-packages\sqlalchemy\pool\base.py", line 753, in _finalize_fairy
    fairy._reset(pool)
  File "C:\Users\tiago\AppData\Local\Programs\Python\Python312\Lib\site-packages\sqlalchemy\pool\base.py", line 1004, in _reset
    pool._dialect.do_rollback(self)
  File "C:\Users\tiago\AppData\Local\Programs\Python\Python312\Lib\site-packages\sqlalchemy\engine\default.py", line 683, in do_rollback
    dbapi_connection.rollback()
sqlite3.ProgrammingError: SQLite objects created in a thread can only be used in that same thread. The object was created in thread id 41448 and this is thread id 59340.
ERROR:sqlalchemy.pool.impl.NullPool:Exception closing connection <sqlite3.Connection object at 0x0000022D889B76A0>
Traceback (most recent call last):
  File "C:\Users\tiago\AppData\Local\Programs\Python\Python312\Lib\site-packages\pydantic\type_adapter.py", line 210, in __init__
    core_schema = _getattr_no_parents(type, '__pydantic_core_schema__')
                  ^^^^^^^^^^^^^^^^^^^^^^^^^^^^^^^^^^^^^^^^^^^^^^^^^^^^^
  File "C:\Users\tiago\AppData\Local\Programs\Python\Python312\Lib\site-packages\pydantic\type_adapter.py", line 98, in _getattr_no_parents
    raise AttributeError(attribute)
AttributeError: __pydantic_core_schema__

During handling of the above exception, another exception occurred:

Traceback (most recent call last):
  File "C:\Users\tiago\AppData\Local\Programs\Python\Python312\Lib\site-packages\sqlalchemy\pool\base.py", line 753, in _finalize_fairy
    fairy._reset(pool)
  File "C:\Users\tiago\AppData\Local\Programs\Python\Python312\Lib\site-packages\sqlalchemy\pool\base.py", line 1004, in _reset
    pool._dialect.do_rollback(self)
  File "C:\Users\tiago\AppData\Local\Programs\Python\Python312\Lib\site-packages\sqlalchemy\engine\default.py", line 683, in do_rollback
    dbapi_connection.rollback()
sqlite3.ProgrammingError: SQLite objects created in a thread can only be used in that same thread. The object was created in thread id 41448 and this is thread id 59340.

During handling of the above exception, another exception occurred:

Traceback (most recent call last):
  File "C:\Users\tiago\AppData\Local\Programs\Python\Python312\Lib\site-packages\sqlalchemy\pool\base.py", line 255, in _close_connection
    self._dialect.do_terminate(connection)
  File "C:\Users\tiago\AppData\Local\Programs\Python\Python312\Lib\site-packages\sqlalchemy\engine\default.py", line 689, in do_terminate
    self.do_close(dbapi_connection)
  File "C:\Users\tiago\AppData\Local\Programs\Python\Python312\Lib\site-packages\sqlalchemy\engine\default.py", line 692, in do_close
    dbapi_connection.close()
sqlite3.ProgrammingError: SQLite objects created in a thread can only be used in that same thread. The object was created in thread id 41448 and this is thread id 59340.
ERROR:sqlalchemy.pool.impl.NullPool:Exception during reset or similar
Traceback (most recent call last):
  File "C:\Users\tiago\AppData\Local\Programs\Python\Python312\Lib\site-packages\pydantic\type_adapter.py", line 210, in __init__
    core_schema = _getattr_no_parents(type, '__pydantic_core_schema__')
                  ^^^^^^^^^^^^^^^^^^^^^^^^^^^^^^^^^^^^^^^^^^^^^^^^^^^^^
  File "C:\Users\tiago\AppData\Local\Programs\Python\Python312\Lib\site-packages\pydantic\type_adapter.py", line 98, in _getattr_no_parents
    raise AttributeError(attribute)
AttributeError: __pydantic_core_schema__

During handling of the above exception, another exception occurred:

Traceback (most recent call last):
  File "C:\Users\tiago\AppData\Local\Programs\Python\Python312\Lib\site-packages\sqlalchemy\pool\base.py", line 753, in _finalize_fairy
    fairy._reset(pool)
  File "C:\Users\tiago\AppData\Local\Programs\Python\Python312\Lib\site-packages\sqlalchemy\pool\base.py", line 1004, in _reset
    pool._dialect.do_rollback(self)
  File "C:\Users\tiago\AppData\Local\Programs\Python\Python312\Lib\site-packages\sqlalchemy\engine\default.py", line 683, in do_rollback
    dbapi_connection.rollback()
sqlite3.ProgrammingError: SQLite objects created in a thread can only be used in that same thread. The object was created in thread id 55452 and this is thread id 59340.
ERROR:sqlalchemy.pool.impl.NullPool:Exception closing connection <sqlite3.Connection object at 0x0000022D889B7100>
Traceback (most recent call last):
  File "C:\Users\tiago\AppData\Local\Programs\Python\Python312\Lib\site-packages\pydantic\type_adapter.py", line 210, in __init__
    core_schema = _getattr_no_parents(type, '__pydantic_core_schema__')
                  ^^^^^^^^^^^^^^^^^^^^^^^^^^^^^^^^^^^^^^^^^^^^^^^^^^^^^
  File "C:\Users\tiago\AppData\Local\Programs\Python\Python312\Lib\site-packages\pydantic\type_adapter.py", line 98, in _getattr_no_parents
    raise AttributeError(attribute)
AttributeError: __pydantic_core_schema__

During handling of the above exception, another exception occurred:

Traceback (most recent call last):
  File "C:\Users\tiago\AppData\Local\Programs\Python\Python312\Lib\site-packages\sqlalchemy\pool\base.py", line 753, in _finalize_fairy
    fairy._reset(pool)
  File "C:\Users\tiago\AppData\Local\Programs\Python\Python312\Lib\site-packages\sqlalchemy\pool\base.py", line 1004, in _reset
    pool._dialect.do_rollback(self)
  File "C:\Users\tiago\AppData\Local\Programs\Python\Python312\Lib\site-packages\sqlalchemy\engine\default.py", line 683, in do_rollback
    dbapi_connection.rollback()
sqlite3.ProgrammingError: SQLite objects created in a thread can only be used in that same thread. The object was created in thread id 55452 and this is thread id 59340.

During handling of the above exception, another exception occurred:

Traceback (most recent call last):
  File "C:\Users\tiago\AppData\Local\Programs\Python\Python312\Lib\site-packages\sqlalchemy\pool\base.py", line 255, in _close_connection
    self._dialect.do_terminate(connection)
  File "C:\Users\tiago\AppData\Local\Programs\Python\Python312\Lib\site-packages\sqlalchemy\engine\default.py", line 689, in do_terminate
    self.do_close(dbapi_connection)
  File "C:\Users\tiago\AppData\Local\Programs\Python\Python312\Lib\site-packages\sqlalchemy\engine\default.py", line 692, in do_close
    dbapi_connection.close()
sqlite3.ProgrammingError: SQLite objects created in a thread can only be used in that same thread. The object was created in thread id 55452 and this is thread id 59340.
DEBUG:root:Adicionando participante de nome: 'Participante 1'
ERROR:sqlalchemy.pool.impl.NullPool:Exception during reset or similar
Traceback (most recent call last):
  File "C:\Users\tiago\AppData\Local\Programs\Python\Python312\Lib\site-packages\sqlalchemy\pool\base.py", line 753, in _finalize_fairy
    fairy._reset(pool)
  File "C:\Users\tiago\AppData\Local\Programs\Python\Python312\Lib\site-packages\sqlalchemy\pool\base.py", line 1004, in _reset
    pool._dialect.do_rollback(self)
  File "C:\Users\tiago\AppData\Local\Programs\Python\Python312\Lib\site-packages\sqlalchemy\engine\default.py", line 683, in do_rollback
    dbapi_connection.rollback()
sqlite3.ProgrammingError: SQLite objects created in a thread can only be used in that same thread. The object was created in thread id 58128 and this is thread id 59340.
ERROR:sqlalchemy.pool.impl.NullPool:Exception closing connection <sqlite3.Connection object at 0x0000022D888325C0>
Traceback (most recent call last):
  File "C:\Users\tiago\AppData\Local\Programs\Python\Python312\Lib\site-packages\sqlalchemy\pool\base.py", line 753, in _finalize_fairy
    fairy._reset(pool)
  File "C:\Users\tiago\AppData\Local\Programs\Python\Python312\Lib\site-packages\sqlalchemy\pool\base.py", line 1004, in _reset
    pool._dialect.do_rollback(self)
  File "C:\Users\tiago\AppData\Local\Programs\Python\Python312\Lib\site-packages\sqlalchemy\engine\default.py", line 683, in do_rollback
    dbapi_connection.rollback()
sqlite3.ProgrammingError: SQLite objects created in a thread can only be used in that same thread. The object was created in thread id 58128 and this is thread id 59340.

During handling of the above exception, another exception occurred:

Traceback (most recent call last):
  File "C:\Users\tiago\AppData\Local\Programs\Python\Python312\Lib\site-packages\sqlalchemy\pool\base.py", line 255, in _close_connection
    self._dialect.do_terminate(connection)
  File "C:\Users\tiago\AppData\Local\Programs\Python\Python312\Lib\site-packages\sqlalchemy\engine\default.py", line 689, in do_terminate
    self.do_close(dbapi_connection)
  File "C:\Users\tiago\AppData\Local\Programs\Python\Python312\Lib\site-packages\sqlalchemy\engine\default.py", line 692, in do_close
    dbapi_connection.close()
sqlite3.ProgrammingError: SQLite objects created in a thread can only be used in that same thread. The object was created in thread id 58128 and this is thread id 59340.
ERROR:sqlalchemy.pool.impl.NullPool:Exception during reset or similar
Traceback (most recent call last):
  File "C:\Users\tiago\AppData\Local\Programs\Python\Python312\Lib\site-packages\sqlalchemy\pool\base.py", line 753, in _finalize_fairy
    fairy._reset(pool)
  File "C:\Users\tiago\AppData\Local\Programs\Python\Python312\Lib\site-packages\sqlalchemy\pool\base.py", line 1004, in _reset
    pool._dialect.do_rollback(self)
  File "C:\Users\tiago\AppData\Local\Programs\Python\Python312\Lib\site-packages\sqlalchemy\engine\default.py", line 683, in do_rollback
    dbapi_connection.rollback()
sqlite3.ProgrammingError: SQLite objects created in a thread can only be used in that same thread. The object was created in thread id 55120 and this is thread id 59340.
ERROR:sqlalchemy.pool.impl.NullPool:Exception closing connection <sqlite3.Connection object at 0x0000022D889B5300>
Traceback (most recent call last):
  File "C:\Users\tiago\AppData\Local\Programs\Python\Python312\Lib\site-packages\sqlalchemy\pool\base.py", line 753, in _finalize_fairy
    fairy._reset(pool)
  File "C:\Users\tiago\AppData\Local\Programs\Python\Python312\Lib\site-packages\sqlalchemy\pool\base.py", line 1004, in _reset
    pool._dialect.do_rollback(self)
  File "C:\Users\tiago\AppData\Local\Programs\Python\Python312\Lib\site-packages\sqlalchemy\engine\default.py", line 683, in do_rollback
    dbapi_connection.rollback()
sqlite3.ProgrammingError: SQLite objects created in a thread can only be used in that same thread. The object was created in thread id 55120 and this is thread id 59340.

During handling of the above exception, another exception occurred:

Traceback (most recent call last):
  File "C:\Users\tiago\AppData\Local\Programs\Python\Python312\Lib\site-packages\sqlalchemy\pool\base.py", line 255, in _close_connection
    self._dialect.do_terminate(connection)
  File "C:\Users\tiago\AppData\Local\Programs\Python\Python312\Lib\site-packages\sqlalchemy\engine\default.py", line 689, in do_terminate
    self.do_close(dbapi_connection)
  File "C:\Users\tiago\AppData\Local\Programs\Python\Python312\Lib\site-packages\sqlalchemy\engine\default.py", line 692, in do_close
    dbapi_connection.close()
sqlite3.ProgrammingError: SQLite objects created in a thread can only be used in that same thread. The object was created in thread id 55120 and this is thread id 59340.
ERROR:sqlalchemy.pool.impl.NullPool:Exception during reset or similar
Traceback (most recent call last):
  File "C:\Users\tiago\AppData\Local\Programs\Python\Python312\Lib\site-packages\sqlalchemy\pool\base.py", line 753, in _finalize_fairy
    fairy._reset(pool)
  File "C:\Users\tiago\AppData\Local\Programs\Python\Python312\Lib\site-packages\sqlalchemy\pool\base.py", line 1004, in _reset
    pool._dialect.do_rollback(self)
  File "C:\Users\tiago\AppData\Local\Programs\Python\Python312\Lib\site-packages\sqlalchemy\engine\default.py", line 683, in do_rollback
    dbapi_connection.rollback()
sqlite3.ProgrammingError: SQLite objects created in a thread can only be used in that same thread. The object was created in thread id 58792 and this is thread id 59340.
ERROR:sqlalchemy.pool.impl.NullPool:Exception closing connection <sqlite3.Connection object at 0x0000022D889B55D0>
Traceback (most recent call last):
  File "C:\Users\tiago\AppData\Local\Programs\Python\Python312\Lib\site-packages\sqlalchemy\pool\base.py", line 753, in _finalize_fairy
    fairy._reset(pool)
  File "C:\Users\tiago\AppData\Local\Programs\Python\Python312\Lib\site-packages\sqlalchemy\pool\base.py", line 1004, in _reset
    pool._dialect.do_rollback(self)
  File "C:\Users\tiago\AppData\Local\Programs\Python\Python312\Lib\site-packages\sqlalchemy\engine\default.py", line 683, in do_rollback
    dbapi_connection.rollback()
sqlite3.ProgrammingError: SQLite objects created in a thread can only be used in that same thread. The object was created in thread id 58792 and this is thread id 59340.

During handling of the above exception, another exception occurred:

Traceback (most recent call last):
  File "C:\Users\tiago\AppData\Local\Programs\Python\Python312\Lib\site-packages\sqlalchemy\pool\base.py", line 255, in _close_connection
    self._dialect.do_terminate(connection)
  File "C:\Users\tiago\AppData\Local\Programs\Python\Python312\Lib\site-packages\sqlalchemy\engine\default.py", line 689, in do_terminate
    self.do_close(dbapi_connection)
  File "C:\Users\tiago\AppData\Local\Programs\Python\Python312\Lib\site-packages\sqlalchemy\engine\default.py", line 692, in do_close
    dbapi_connection.close()
sqlite3.ProgrammingError: SQLite objects created in a thread can only be used in that same thread. The object was created in thread id 58792 and this is thread id 59340.
ERROR:sqlalchemy.pool.impl.NullPool:Exception during reset or similar
Traceback (most recent call last):
  File "C:\Users\tiago\AppData\Local\Programs\Python\Python312\Lib\site-packages\sqlalchemy\pool\base.py", line 753, in _finalize_fairy
    fairy._reset(pool)
  File "C:\Users\tiago\AppData\Local\Programs\Python\Python312\Lib\site-packages\sqlalchemy\pool\base.py", line 1004, in _reset
    pool._dialect.do_rollback(self)
  File "C:\Users\tiago\AppData\Local\Programs\Python\Python312\Lib\site-packages\sqlalchemy\engine\default.py", line 683, in do_rollback
    dbapi_connection.rollback()
sqlite3.ProgrammingError: SQLite objects created in a thread can only be used in that same thread. The object was created in thread id 53220 and this is thread id 59340.
ERROR:sqlalchemy.pool.impl.NullPool:Exception closing connection <sqlite3.Connection object at 0x0000022D889B67A0>
Traceback (most recent call last):
  File "C:\Users\tiago\AppData\Local\Programs\Python\Python312\Lib\site-packages\sqlalchemy\pool\base.py", line 753, in _finalize_fairy
    fairy._reset(pool)
  File "C:\Users\tiago\AppData\Local\Programs\Python\Python312\Lib\site-packages\sqlalchemy\pool\base.py", line 1004, in _reset
    pool._dialect.do_rollback(self)
  File "C:\Users\tiago\AppData\Local\Programs\Python\Python312\Lib\site-packages\sqlalchemy\engine\default.py", line 683, in do_rollback
    dbapi_connection.rollback()
sqlite3.ProgrammingError: SQLite objects created in a thread can only be used in that same thread. The object was created in thread id 53220 and this is thread id 59340.

During handling of the above exception, another exception occurred:

Traceback (most recent call last):
  File "C:\Users\tiago\AppData\Local\Programs\Python\Python312\Lib\site-packages\sqlalchemy\pool\base.py", line 255, in _close_connection
    self._dialect.do_terminate(connection)
  File "C:\Users\tiago\AppData\Local\Programs\Python\Python312\Lib\site-packages\sqlalchemy\engine\default.py", line 689, in do_terminate
    self.do_close(dbapi_connection)
  File "C:\Users\tiago\AppData\Local\Programs\Python\Python312\Lib\site-packages\sqlalchemy\engine\default.py", line 692, in do_close
    dbapi_connection.close()
sqlite3.ProgrammingError: SQLite objects created in a thread can only be used in that same thread. The object was created in thread id 53220 and this is thread id 59340.
ERROR:sqlalchemy.pool.impl.NullPool:Exception during reset or similar
Traceback (most recent call last):
  File "C:\Users\tiago\AppData\Local\Programs\Python\Python312\Lib\site-packages\sqlalchemy\pool\base.py", line 753, in _finalize_fairy
    fairy._reset(pool)
  File "C:\Users\tiago\AppData\Local\Programs\Python\Python312\Lib\site-packages\sqlalchemy\pool\base.py", line 1004, in _reset
    pool._dialect.do_rollback(self)
  File "C:\Users\tiago\AppData\Local\Programs\Python\Python312\Lib\site-packages\sqlalchemy\engine\default.py", line 683, in do_rollback
    dbapi_connection.rollback()
sqlite3.ProgrammingError: SQLite objects created in a thread can only be used in that same thread. The object was created in thread id 51920 and this is thread id 59340.
ERROR:sqlalchemy.pool.impl.NullPool:Exception closing connection <sqlite3.Connection object at 0x0000022D889B6E30>
Traceback (most recent call last):
  File "C:\Users\tiago\AppData\Local\Programs\Python\Python312\Lib\site-packages\sqlalchemy\pool\base.py", line 753, in _finalize_fairy
    fairy._reset(pool)
  File "C:\Users\tiago\AppData\Local\Programs\Python\Python312\Lib\site-packages\sqlalchemy\pool\base.py", line 1004, in _reset
    pool._dialect.do_rollback(self)
  File "C:\Users\tiago\AppData\Local\Programs\Python\Python312\Lib\site-packages\sqlalchemy\engine\default.py", line 683, in do_rollback
    dbapi_connection.rollback()
sqlite3.ProgrammingError: SQLite objects created in a thread can only be used in that same thread. The object was created in thread id 51920 and this is thread id 59340.

During handling of the above exception, another exception occurred:

Traceback (most recent call last):
  File "C:\Users\tiago\AppData\Local\Programs\Python\Python312\Lib\site-packages\sqlalchemy\pool\base.py", line 255, in _close_connection
    self._dialect.do_terminate(connection)
  File "C:\Users\tiago\AppData\Local\Programs\Python\Python312\Lib\site-packages\sqlalchemy\engine\default.py", line 689, in do_terminate
    self.do_close(dbapi_connection)
  File "C:\Users\tiago\AppData\Local\Programs\Python\Python312\Lib\site-packages\sqlalchemy\engine\default.py", line 692, in do_close
    dbapi_connection.close()
sqlite3.ProgrammingError: SQLite objects created in a thread can only be used in that same thread. The object was created in thread id 51920 and this is thread id 59340.
ERROR:sqlalchemy.pool.impl.NullPool:Exception during reset or similar
Traceback (most recent call last):
  File "C:\Users\tiago\AppData\Local\Programs\Python\Python312\Lib\site-packages\sqlalchemy\pool\base.py", line 753, in _finalize_fairy
    fairy._reset(pool)
  File "C:\Users\tiago\AppData\Local\Programs\Python\Python312\Lib\site-packages\sqlalchemy\pool\base.py", line 1004, in _reset
    pool._dialect.do_rollback(self)
  File "C:\Users\tiago\AppData\Local\Programs\Python\Python312\Lib\site-packages\sqlalchemy\engine\default.py", line 683, in do_rollback
    dbapi_connection.rollback()
sqlite3.ProgrammingError: SQLite objects created in a thread can only be used in that same thread. The object was created in thread id 59072 and this is thread id 59340.
ERROR:sqlalchemy.pool.impl.NullPool:Exception closing connection <sqlite3.Connection object at 0x0000022D889B7010>
Traceback (most recent call last):
  File "C:\Users\tiago\AppData\Local\Programs\Python\Python312\Lib\site-packages\sqlalchemy\pool\base.py", line 753, in _finalize_fairy
    fairy._reset(pool)
  File "C:\Users\tiago\AppData\Local\Programs\Python\Python312\Lib\site-packages\sqlalchemy\pool\base.py", line 1004, in _reset
    pool._dialect.do_rollback(self)
  File "C:\Users\tiago\AppData\Local\Programs\Python\Python312\Lib\site-packages\sqlalchemy\engine\default.py", line 683, in do_rollback
    dbapi_connection.rollback()
sqlite3.ProgrammingError: SQLite objects created in a thread can only be used in that same thread. The object was created in thread id 59072 and this is thread id 59340.

During handling of the above exception, another exception occurred:

Traceback (most recent call last):
  File "C:\Users\tiago\AppData\Local\Programs\Python\Python312\Lib\site-packages\sqlalchemy\pool\base.py", line 255, in _close_connection
    self._dialect.do_terminate(connection)
  File "C:\Users\tiago\AppData\Local\Programs\Python\Python312\Lib\site-packages\sqlalchemy\engine\default.py", line 689, in do_terminate
    self.do_close(dbapi_connection)
  File "C:\Users\tiago\AppData\Local\Programs\Python\Python312\Lib\site-packages\sqlalchemy\engine\default.py", line 692, in do_close
    dbapi_connection.close()
sqlite3.ProgrammingError: SQLite objects created in a thread can only be used in that same thread. The object was created in thread id 59072 and this is thread id 59340.
ERROR:sqlalchemy.pool.impl.NullPool:Exception during reset or similar
Traceback (most recent call last):
  File "C:\Users\tiago\AppData\Local\Programs\Python\Python312\Lib\site-packages\sqlalchemy\pool\base.py", line 753, in _finalize_fairy
    fairy._reset(pool)
  File "C:\Users\tiago\AppData\Local\Programs\Python\Python312\Lib\site-packages\sqlalchemy\pool\base.py", line 1004, in _reset
    pool._dialect.do_rollback(self)
  File "C:\Users\tiago\AppData\Local\Programs\Python\Python312\Lib\site-packages\sqlalchemy\engine\default.py", line 683, in do_rollback
    dbapi_connection.rollback()
sqlite3.ProgrammingError: SQLite objects created in a thread can only be used in that same thread. The object was created in thread id 17376 and this is thread id 59340.
ERROR:sqlalchemy.pool.impl.NullPool:Exception closing connection <sqlite3.Connection object at 0x0000022D889B58A0>
Traceback (most recent call last):
  File "C:\Users\tiago\AppData\Local\Programs\Python\Python312\Lib\site-packages\sqlalchemy\pool\base.py", line 753, in _finalize_fairy
    fairy._reset(pool)
  File "C:\Users\tiago\AppData\Local\Programs\Python\Python312\Lib\site-packages\sqlalchemy\pool\base.py", line 1004, in _reset
    pool._dialect.do_rollback(self)
  File "C:\Users\tiago\AppData\Local\Programs\Python\Python312\Lib\site-packages\sqlalchemy\engine\default.py", line 683, in do_rollback
    dbapi_connection.rollback()
sqlite3.ProgrammingError: SQLite objects created in a thread can only be used in that same thread. The object was created in thread id 17376 and this is thread id 59340.

During handling of the above exception, another exception occurred:

Traceback (most recent call last):
  File "C:\Users\tiago\AppData\Local\Programs\Python\Python312\Lib\site-packages\sqlalchemy\pool\base.py", line 255, in _close_connection
    self._dialect.do_terminate(connection)
  File "C:\Users\tiago\AppData\Local\Programs\Python\Python312\Lib\site-packages\sqlalchemy\engine\default.py", line 689, in do_terminate
    self.do_close(dbapi_connection)
  File "C:\Users\tiago\AppData\Local\Programs\Python\Python312\Lib\site-packages\sqlalchemy\engine\default.py", line 692, in do_close
    dbapi_connection.close()
sqlite3.ProgrammingError: SQLite objects created in a thread can only be used in that same thread. The object was created in thread id 17376 and this is thread id 59340.
ERROR:sqlalchemy.pool.impl.NullPool:Exception during reset or similar
Traceback (most recent call last):
  File "C:\Users\tiago\AppData\Local\Programs\Python\Python312\Lib\site-packages\sqlalchemy\pool\base.py", line 753, in _finalize_fairy
    fairy._reset(pool)
  File "C:\Users\tiago\AppData\Local\Programs\Python\Python312\Lib\site-packages\sqlalchemy\pool\base.py", line 1004, in _reset
    pool._dialect.do_rollback(self)
  File "C:\Users\tiago\AppData\Local\Programs\Python\Python312\Lib\site-packages\sqlalchemy\engine\default.py", line 683, in do_rollback
    dbapi_connection.rollback()
sqlite3.ProgrammingError: SQLite objects created in a thread can only be used in that same thread. The object was created in thread id 58780 and this is thread id 59340.
ERROR:sqlalchemy.pool.impl.NullPool:Exception closing connection <sqlite3.Connection object at 0x0000022D887976A0>
Traceback (most recent call last):
  File "C:\Users\tiago\AppData\Local\Programs\Python\Python312\Lib\site-packages\sqlalchemy\pool\base.py", line 753, in _finalize_fairy
    fairy._reset(pool)
  File "C:\Users\tiago\AppData\Local\Programs\Python\Python312\Lib\site-packages\sqlalchemy\pool\base.py", line 1004, in _reset
    pool._dialect.do_rollback(self)
  File "C:\Users\tiago\AppData\Local\Programs\Python\Python312\Lib\site-packages\sqlalchemy\engine\default.py", line 683, in do_rollback
    dbapi_connection.rollback()
sqlite3.ProgrammingError: SQLite objects created in a thread can only be used in that same thread. The object was created in thread id 58780 and this is thread id 59340.

During handling of the above exception, another exception occurred:

Traceback (most recent call last):
  File "C:\Users\tiago\AppData\Local\Programs\Python\Python312\Lib\site-packages\sqlalchemy\pool\base.py", line 255, in _close_connection
    self._dialect.do_terminate(connection)
  File "C:\Users\tiago\AppData\Local\Programs\Python\Python312\Lib\site-packages\sqlalchemy\engine\default.py", line 689, in do_terminate
    self.do_close(dbapi_connection)
  File "C:\Users\tiago\AppData\Local\Programs\Python\Python312\Lib\site-packages\sqlalchemy\engine\default.py", line 692, in do_close
    dbapi_connection.close()
sqlite3.ProgrammingError: SQLite objects created in a thread can only be used in that same thread. The object was created in thread id 58780 and this is thread id 59340.
ERROR:sqlalchemy.pool.impl.NullPool:Exception during reset or similar
Traceback (most recent call last):
  File "C:\Users\tiago\AppData\Local\Programs\Python\Python312\Lib\site-packages\sqlalchemy\pool\base.py", line 753, in _finalize_fairy
    fairy._reset(pool)
  File "C:\Users\tiago\AppData\Local\Programs\Python\Python312\Lib\site-packages\sqlalchemy\pool\base.py", line 1004, in _reset
    pool._dialect.do_rollback(self)
  File "C:\Users\tiago\AppData\Local\Programs\Python\Python312\Lib\site-packages\sqlalchemy\engine\default.py", line 683, in do_rollback
    dbapi_connection.rollback()
sqlite3.ProgrammingError: SQLite objects created in a thread can only be used in that same thread. The object was created in thread id 57220 and this is thread id 59340.
ERROR:sqlalchemy.pool.impl.NullPool:Exception closing connection <sqlite3.Connection object at 0x0000022D889B71F0>
Traceback (most recent call last):
  File "C:\Users\tiago\AppData\Local\Programs\Python\Python312\Lib\site-packages\sqlalchemy\pool\base.py", line 753, in _finalize_fairy
    fairy._reset(pool)
  File "C:\Users\tiago\AppData\Local\Programs\Python\Python312\Lib\site-packages\sqlalchemy\pool\base.py", line 1004, in _reset
    pool._dialect.do_rollback(self)
  File "C:\Users\tiago\AppData\Local\Programs\Python\Python312\Lib\site-packages\sqlalchemy\engine\default.py", line 683, in do_rollback
    dbapi_connection.rollback()
sqlite3.ProgrammingError: SQLite objects created in a thread can only be used in that same thread. The object was created in thread id 57220 and this is thread id 59340.

During handling of the above exception, another exception occurred:

Traceback (most recent call last):
  File "C:\Users\tiago\AppData\Local\Programs\Python\Python312\Lib\site-packages\sqlalchemy\pool\base.py", line 255, in _close_connection
    self._dialect.do_terminate(connection)
  File "C:\Users\tiago\AppData\Local\Programs\Python\Python312\Lib\site-packages\sqlalchemy\engine\default.py", line 689, in do_terminate
    self.do_close(dbapi_connection)
  File "C:\Users\tiago\AppData\Local\Programs\Python\Python312\Lib\site-packages\sqlalchemy\engine\default.py", line 692, in do_close
    dbapi_connection.close()
sqlite3.ProgrammingError: SQLite objects created in a thread can only be used in that same thread. The object was created in thread id 57220 and this is thread id 59340.
ERROR:sqlalchemy.pool.impl.NullPool:Exception during reset or similar
Traceback (most recent call last):
  File "C:\Users\tiago\AppData\Local\Programs\Python\Python312\Lib\site-packages\sqlalchemy\pool\base.py", line 753, in _finalize_fairy
    fairy._reset(pool)
  File "C:\Users\tiago\AppData\Local\Programs\Python\Python312\Lib\site-packages\sqlalchemy\pool\base.py", line 1004, in _reset
    pool._dialect.do_rollback(self)
  File "C:\Users\tiago\AppData\Local\Programs\Python\Python312\Lib\site-packages\sqlalchemy\engine\default.py", line 683, in do_rollback
    dbapi_connection.rollback()
sqlite3.ProgrammingError: SQLite objects created in a thread can only be used in that same thread. The object was created in thread id 58804 and this is thread id 59340.
ERROR:sqlalchemy.pool.impl.NullPool:Exception closing connection <sqlite3.Connection object at 0x0000022D889B73D0>
Traceback (most recent call last):
  File "C:\Users\tiago\AppData\Local\Programs\Python\Python312\Lib\site-packages\sqlalchemy\pool\base.py", line 753, in _finalize_fairy
    fairy._reset(pool)
  File "C:\Users\tiago\AppData\Local\Programs\Python\Python312\Lib\site-packages\sqlalchemy\pool\base.py", line 1004, in _reset
    pool._dialect.do_rollback(self)
  File "C:\Users\tiago\AppData\Local\Programs\Python\Python312\Lib\site-packages\sqlalchemy\engine\default.py", line 683, in do_rollback
    dbapi_connection.rollback()
sqlite3.ProgrammingError: SQLite objects created in a thread can only be used in that same thread. The object was created in thread id 58804 and this is thread id 59340.

During handling of the above exception, another exception occurred:

Traceback (most recent call last):
  File "C:\Users\tiago\AppData\Local\Programs\Python\Python312\Lib\site-packages\sqlalchemy\pool\base.py", line 255, in _close_connection
    self._dialect.do_terminate(connection)
  File "C:\Users\tiago\AppData\Local\Programs\Python\Python312\Lib\site-packages\sqlalchemy\engine\default.py", line 689, in do_terminate
    self.do_close(dbapi_connection)
  File "C:\Users\tiago\AppData\Local\Programs\Python\Python312\Lib\site-packages\sqlalchemy\engine\default.py", line 692, in do_close
    dbapi_connection.close()
sqlite3.ProgrammingError: SQLite objects created in a thread can only be used in that same thread. The object was created in thread id 58804 and this is thread id 59340.
DEBUG:root:Adicionado participante de nome: 'Participante 1'
INFO:werkzeug:127.0.0.1 - - [17/Apr/2024 09:33:37] "POST /participante HTTP/1.1" 200 -
DEBUG:root:Consulta todos os participantes
DEBUG:root:Consulta todos os centrodeinteresses
INFO:werkzeug:127.0.0.1 - - [17/Apr/2024 09:33:37] "GET /participante?eventoId=2 HTTP/1.1" 200 -
INFO:werkzeug:127.0.0.1 - - [17/Apr/2024 09:33:37] "GET /centrodeinteresse?eventoId=2 HTTP/1.1" 200 -
DEBUG:root:Consulta todos os centros de interesse
ERROR:sqlalchemy.pool.impl.NullPool:Exception during reset or similar
Traceback (most recent call last):
  File "C:\Users\tiago\AppData\Local\Programs\Python\Python312\Lib\site-packages\sqlalchemy\pool\base.py", line 753, in _finalize_fairy
    fairy._reset(pool)
  File "C:\Users\tiago\AppData\Local\Programs\Python\Python312\Lib\site-packages\sqlalchemy\pool\base.py", line 1004, in _reset
    pool._dialect.do_rollback(self)
  File "C:\Users\tiago\AppData\Local\Programs\Python\Python312\Lib\site-packages\sqlalchemy\engine\default.py", line 683, in do_rollback
    dbapi_connection.rollback()
sqlite3.ProgrammingError: SQLite objects created in a thread can only be used in that same thread. The object was created in thread id 11080 and this is thread id 55316.
ERROR:sqlalchemy.pool.impl.NullPool:Exception closing connection <sqlite3.Connection object at 0x0000022D887DD210>
Traceback (most recent call last):
  File "C:\Users\tiago\AppData\Local\Programs\Python\Python312\Lib\site-packages\sqlalchemy\pool\base.py", line 753, in _finalize_fairy
    fairy._reset(pool)
  File "C:\Users\tiago\AppData\Local\Programs\Python\Python312\Lib\site-packages\sqlalchemy\pool\base.py", line 1004, in _reset
    pool._dialect.do_rollback(self)
  File "C:\Users\tiago\AppData\Local\Programs\Python\Python312\Lib\site-packages\sqlalchemy\engine\default.py", line 683, in do_rollback
    dbapi_connection.rollback()
sqlite3.ProgrammingError: SQLite objects created in a thread can only be used in that same thread. The object was created in thread id 11080 and this is thread id 55316.

During handling of the above exception, another exception occurred:

Traceback (most recent call last):
  File "C:\Users\tiago\AppData\Local\Programs\Python\Python312\Lib\site-packages\sqlalchemy\pool\base.py", line 255, in _close_connection
    self._dialect.do_terminate(connection)
  File "C:\Users\tiago\AppData\Local\Programs\Python\Python312\Lib\site-packages\sqlalchemy\engine\default.py", line 689, in do_terminate
    self.do_close(dbapi_connection)
  File "C:\Users\tiago\AppData\Local\Programs\Python\Python312\Lib\site-packages\sqlalchemy\engine\default.py", line 692, in do_close
    dbapi_connection.close()
sqlite3.ProgrammingError: SQLite objects created in a thread can only be used in that same thread. The object was created in thread id 11080 and this is thread id 55316.
ERROR:sqlalchemy.pool.impl.NullPool:Exception during reset or similar
Traceback (most recent call last):
  File "C:\Users\tiago\AppData\Local\Programs\Python\Python312\Lib\site-packages\sqlalchemy\pool\base.py", line 753, in _finalize_fairy
    fairy._reset(pool)
  File "C:\Users\tiago\AppData\Local\Programs\Python\Python312\Lib\site-packages\sqlalchemy\pool\base.py", line 1004, in _reset
    pool._dialect.do_rollback(self)
  File "C:\Users\tiago\AppData\Local\Programs\Python\Python312\Lib\site-packages\sqlalchemy\engine\default.py", line 683, in do_rollback
    dbapi_connection.rollback()
sqlite3.ProgrammingError: SQLite objects created in a thread can only be used in that same thread. The object was created in thread id 46048 and this is thread id 55316.
ERROR:sqlalchemy.pool.impl.NullPool:Exception closing connection <sqlite3.Connection object at 0x0000022D889B72E0>
Traceback (most recent call last):
  File "C:\Users\tiago\AppData\Local\Programs\Python\Python312\Lib\site-packages\sqlalchemy\pool\base.py", line 753, in _finalize_fairy
    fairy._reset(pool)
  File "C:\Users\tiago\AppData\Local\Programs\Python\Python312\Lib\site-packages\sqlalchemy\pool\base.py", line 1004, in _reset
    pool._dialect.do_rollback(self)
  File "C:\Users\tiago\AppData\Local\Programs\Python\Python312\Lib\site-packages\sqlalchemy\engine\default.py", line 683, in do_rollback
    dbapi_connection.rollback()
sqlite3.ProgrammingError: SQLite objects created in a thread can only be used in that same thread. The object was created in thread id 46048 and this is thread id 55316.

During handling of the above exception, another exception occurred:

Traceback (most recent call last):
  File "C:\Users\tiago\AppData\Local\Programs\Python\Python312\Lib\site-packages\sqlalchemy\pool\base.py", line 255, in _close_connection
    self._dialect.do_terminate(connection)
  File "C:\Users\tiago\AppData\Local\Programs\Python\Python312\Lib\site-packages\sqlalchemy\engine\default.py", line 689, in do_terminate
    self.do_close(dbapi_connection)
  File "C:\Users\tiago\AppData\Local\Programs\Python\Python312\Lib\site-packages\sqlalchemy\engine\default.py", line 692, in do_close
    dbapi_connection.close()
sqlite3.ProgrammingError: SQLite objects created in a thread can only be used in that same thread. The object was created in thread id 46048 and this is thread id 55316.
INFO:werkzeug:127.0.0.1 - - [17/Apr/2024 09:33:41] "GET /participante/centrosdeinteresse?eventoId=2 HTTP/1.1" 200 -
ERROR:sqlalchemy.pool.impl.NullPool:Exception during reset or similar
Traceback (most recent call last):
  File "C:\Users\tiago\AppData\Local\Programs\Python\Python312\Lib\site-packages\sqlalchemy\pool\base.py", line 753, in _finalize_fairy
    fairy._reset(pool)
  File "C:\Users\tiago\AppData\Local\Programs\Python\Python312\Lib\site-packages\sqlalchemy\pool\base.py", line 1004, in _reset
    pool._dialect.do_rollback(self)
  File "C:\Users\tiago\AppData\Local\Programs\Python\Python312\Lib\site-packages\sqlalchemy\engine\default.py", line 683, in do_rollback
    dbapi_connection.rollback()
sqlite3.ProgrammingError: SQLite objects created in a thread can only be used in that same thread. The object was created in thread id 59340 and this is thread id 59336.
ERROR:sqlalchemy.pool.impl.NullPool:Exception closing connection <sqlite3.Connection object at 0x0000022D889B7790>
Traceback (most recent call last):
  File "C:\Users\tiago\AppData\Local\Programs\Python\Python312\Lib\site-packages\sqlalchemy\pool\base.py", line 753, in _finalize_fairy
    fairy._reset(pool)
  File "C:\Users\tiago\AppData\Local\Programs\Python\Python312\Lib\site-packages\sqlalchemy\pool\base.py", line 1004, in _reset
    pool._dialect.do_rollback(self)
  File "C:\Users\tiago\AppData\Local\Programs\Python\Python312\Lib\site-packages\sqlalchemy\engine\default.py", line 683, in do_rollback
    dbapi_connection.rollback()
sqlite3.ProgrammingError: SQLite objects created in a thread can only be used in that same thread. The object was created in thread id 59340 and this is thread id 59336.

During handling of the above exception, another exception occurred:

Traceback (most recent call last):
  File "C:\Users\tiago\AppData\Local\Programs\Python\Python312\Lib\site-packages\sqlalchemy\pool\base.py", line 255, in _close_connection
    self._dialect.do_terminate(connection)
  File "C:\Users\tiago\AppData\Local\Programs\Python\Python312\Lib\site-packages\sqlalchemy\engine\default.py", line 689, in do_terminate
    self.do_close(dbapi_connection)
  File "C:\Users\tiago\AppData\Local\Programs\Python\Python312\Lib\site-packages\sqlalchemy\engine\default.py", line 692, in do_close
    dbapi_connection.close()
sqlite3.ProgrammingError: SQLite objects created in a thread can only be used in that same thread. The object was created in thread id 59340 and this is thread id 59336.
ERROR:sqlalchemy.pool.impl.NullPool:Exception during reset or similar
Traceback (most recent call last):
  File "C:\Users\tiago\AppData\Local\Programs\Python\Python312\Lib\site-packages\sqlalchemy\pool\base.py", line 753, in _finalize_fairy
    fairy._reset(pool)
  File "C:\Users\tiago\AppData\Local\Programs\Python\Python312\Lib\site-packages\sqlalchemy\pool\base.py", line 1004, in _reset
    pool._dialect.do_rollback(self)
  File "C:\Users\tiago\AppData\Local\Programs\Python\Python312\Lib\site-packages\sqlalchemy\engine\default.py", line 683, in do_rollback
    dbapi_connection.rollback()
sqlite3.ProgrammingError: SQLite objects created in a thread can only be used in that same thread. The object was created in thread id 55316 and this is thread id 59336.
ERROR:sqlalchemy.pool.impl.NullPool:Exception closing connection <sqlite3.Connection object at 0x0000022D887973D0>
Traceback (most recent call last):
  File "C:\Users\tiago\AppData\Local\Programs\Python\Python312\Lib\site-packages\sqlalchemy\pool\base.py", line 753, in _finalize_fairy
    fairy._reset(pool)
  File "C:\Users\tiago\AppData\Local\Programs\Python\Python312\Lib\site-packages\sqlalchemy\pool\base.py", line 1004, in _reset
    pool._dialect.do_rollback(self)
  File "C:\Users\tiago\AppData\Local\Programs\Python\Python312\Lib\site-packages\sqlalchemy\engine\default.py", line 683, in do_rollback
    dbapi_connection.rollback()
sqlite3.ProgrammingError: SQLite objects created in a thread can only be used in that same thread. The object was created in thread id 55316 and this is thread id 59336.

During handling of the above exception, another exception occurred:

Traceback (most recent call last):
  File "C:\Users\tiago\AppData\Local\Programs\Python\Python312\Lib\site-packages\sqlalchemy\pool\base.py", line 255, in _close_connection
    self._dialect.do_terminate(connection)
  File "C:\Users\tiago\AppData\Local\Programs\Python\Python312\Lib\site-packages\sqlalchemy\engine\default.py", line 689, in do_terminate
    self.do_close(dbapi_connection)
  File "C:\Users\tiago\AppData\Local\Programs\Python\Python312\Lib\site-packages\sqlalchemy\engine\default.py", line 692, in do_close
    dbapi_connection.close()
sqlite3.ProgrammingError: SQLite objects created in a thread can only be used in that same thread. The object was created in thread id 55316 and this is thread id 59336.
INFO:werkzeug:[31m[1mWARNING: This is a development server. Do not use it in a production deployment. Use a production WSGI server instead.[0m
 * Running on http://127.0.0.1:5000
INFO:werkzeug:[33mPress CTRL+C to quit[0m
