DEBUG:root:Consulta todos os eventos
ERROR:app:Exception on /evento [GET]
Traceback (most recent call last):
  File "C:\Users\tiago\AppData\Local\Programs\Python\Python312\Lib\site-packages\sqlalchemy\engine\base.py", line 1900, in _execute_context
    self.dialect.do_execute(
  File "C:\Users\tiago\AppData\Local\Programs\Python\Python312\Lib\site-packages\sqlalchemy\engine\default.py", line 736, in do_execute
    cursor.execute(statement, parameters)
sqlite3.OperationalError: no such table: evento

The above exception was the direct cause of the following exception:

Traceback (most recent call last):
  File "C:\Estudo\PÃ³s\Sprint_FullStackBasico\TestesDeImplantacaoEPull\eventosapi\Aplicacao\app.py", line 69, in get_evento
    return mapeaentidades_paraschemaeventos(eventos), 200
           ^^^^^^^^^^^^^^^^^^^^^^^^^^^^^^^^^^^^^^^^^
  File "C:\Estudo\PÃ³s\Sprint_FullStackBasico\TestesDeImplantacaoEPull\eventosapi\Aplicacao\schemas\evento.py", line 37, in mapeaentidades_paraschemaeventos
    for evento in eventos:
  File "C:\Users\tiago\AppData\Local\Programs\Python\Python312\Lib\site-packages\sqlalchemy\orm\query.py", line 2900, in __iter__
    return self._iter().__iter__()
           ^^^^^^^^^^^^
  File "C:\Users\tiago\AppData\Local\Programs\Python\Python312\Lib\site-packages\sqlalchemy\orm\query.py", line 2907, in _iter
    result = self.session.execute(
             ^^^^^^^^^^^^^^^^^^^^^
  File "C:\Users\tiago\AppData\Local\Programs\Python\Python312\Lib\site-packages\sqlalchemy\orm\session.py", line 1712, in execute
    result = conn._execute_20(statement, params or {}, execution_options)
             ^^^^^^^^^^^^^^^^^^^^^^^^^^^^^^^^^^^^^^^^^^^^^^^^^^^^^^^^^^^^
  File "C:\Users\tiago\AppData\Local\Programs\Python\Python312\Lib\site-packages\sqlalchemy\engine\base.py", line 1705, in _execute_20
    return meth(self, args_10style, kwargs_10style, execution_options)
           ^^^^^^^^^^^^^^^^^^^^^^^^^^^^^^^^^^^^^^^^^^^^^^^^^^^^^^^^^^^
  File "C:\Users\tiago\AppData\Local\Programs\Python\Python312\Lib\site-packages\sqlalchemy\sql\elements.py", line 333, in _execute_on_connection
    return connection._execute_clauseelement(
           ^^^^^^^^^^^^^^^^^^^^^^^^^^^^^^^^^^
  File "C:\Users\tiago\AppData\Local\Programs\Python\Python312\Lib\site-packages\sqlalchemy\engine\base.py", line 1572, in _execute_clauseelement
    ret = self._execute_context(
          ^^^^^^^^^^^^^^^^^^^^^^
  File "C:\Users\tiago\AppData\Local\Programs\Python\Python312\Lib\site-packages\sqlalchemy\engine\base.py", line 1943, in _execute_context
    self._handle_dbapi_exception(
  File "C:\Users\tiago\AppData\Local\Programs\Python\Python312\Lib\site-packages\sqlalchemy\engine\base.py", line 2124, in _handle_dbapi_exception
    util.raise_(
  File "C:\Users\tiago\AppData\Local\Programs\Python\Python312\Lib\site-packages\sqlalchemy\util\compat.py", line 208, in raise_
    raise exception
  File "C:\Users\tiago\AppData\Local\Programs\Python\Python312\Lib\site-packages\sqlalchemy\engine\base.py", line 1900, in _execute_context
    self.dialect.do_execute(
  File "C:\Users\tiago\AppData\Local\Programs\Python\Python312\Lib\site-packages\sqlalchemy\engine\default.py", line 736, in do_execute
    cursor.execute(statement, parameters)
sqlalchemy.exc.OperationalError: (sqlite3.OperationalError) no such table: evento
[SQL: SELECT evento.id AS evento_id, evento.nome AS evento_nome, evento.ativo AS evento_ativo, evento.datainicio AS evento_datainicio, evento.datafim AS evento_datafim, evento.idstatusevento AS evento_idstatusevento, evento.idcentrosdeinteresse AS evento_idcentrosdeinteresse 
FROM evento 
WHERE evento.ativo = ?]
[parameters: (1,)]
(Background on this error at: https://sqlalche.me/e/14/e3q8)

During handling of the above exception, another exception occurred:

Traceback (most recent call last):
  File "C:\Users\tiago\AppData\Local\Programs\Python\Python312\Lib\site-packages\flask\app.py", line 2073, in wsgi_app
    response = self.full_dispatch_request()
               ^^^^^^^^^^^^^^^^^^^^^^^^^^^^
  File "C:\Users\tiago\AppData\Local\Programs\Python\Python312\Lib\site-packages\flask\app.py", line 1519, in full_dispatch_request
    rv = self.handle_user_exception(e)
         ^^^^^^^^^^^^^^^^^^^^^^^^^^^^^
  File "C:\Users\tiago\AppData\Local\Programs\Python\Python312\Lib\site-packages\flask_cors\extension.py", line 165, in wrapped_function
    return cors_after_request(app.make_response(f(*args, **kwargs)))
                                                ^^^^^^^^^^^^^^^^^^
  File "C:\Users\tiago\AppData\Local\Programs\Python\Python312\Lib\site-packages\flask\app.py", line 1517, in full_dispatch_request
    rv = self.dispatch_request()
         ^^^^^^^^^^^^^^^^^^^^^^^
  File "C:\Users\tiago\AppData\Local\Programs\Python\Python312\Lib\site-packages\flask\app.py", line 1503, in dispatch_request
    return self.ensure_sync(self.view_functions[rule.endpoint])(**req.view_args)
           ^^^^^^^^^^^^^^^^^^^^^^^^^^^^^^^^^^^^^^^^^^^^^^^^^^^^^^^^^^^^^^^^^^^^^
  File "C:\Users\tiago\AppData\Local\Programs\Python\Python312\Lib\site-packages\flask_openapi3\scaffold.py", line 117, in view_func
    response = func(**func_kwargs)
               ^^^^^^^^^^^^^^^^^^^
  File "C:\Estudo\PÃ³s\Sprint_FullStackBasico\TestesDeImplantacaoEPull\eventosapi\Aplicacao\app.py", line 72, in get_evento
    #alert("Erro ao consultar")
    ^^^^^
NameError: name 'alert' is not defined. Did you mean: 'anext'?
INFO:werkzeug:127.0.0.1 - - [17/Apr/2024 00:01:19] "[35m[1mGET /evento HTTP/1.1[0m" 500 -
ERROR:sqlalchemy.pool.impl.NullPool:Exception during reset or similar
Traceback (most recent call last):
  File "C:\Users\tiago\AppData\Local\Programs\Python\Python312\Lib\site-packages\sqlalchemy\pool\base.py", line 753, in _finalize_fairy
    fairy._reset(pool)
  File "C:\Users\tiago\AppData\Local\Programs\Python\Python312\Lib\site-packages\sqlalchemy\pool\base.py", line 1004, in _reset
    pool._dialect.do_rollback(self)
  File "C:\Users\tiago\AppData\Local\Programs\Python\Python312\Lib\site-packages\sqlalchemy\engine\default.py", line 683, in do_rollback
    dbapi_connection.rollback()
sqlite3.ProgrammingError: SQLite objects created in a thread can only be used in that same thread. The object was created in thread id 45496 and this is thread id 45380.
ERROR:sqlalchemy.pool.impl.NullPool:Exception closing connection <sqlite3.Connection object at 0x0000021CD9F023E0>
Traceback (most recent call last):
  File "C:\Users\tiago\AppData\Local\Programs\Python\Python312\Lib\site-packages\sqlalchemy\pool\base.py", line 753, in _finalize_fairy
    fairy._reset(pool)
  File "C:\Users\tiago\AppData\Local\Programs\Python\Python312\Lib\site-packages\sqlalchemy\pool\base.py", line 1004, in _reset
    pool._dialect.do_rollback(self)
  File "C:\Users\tiago\AppData\Local\Programs\Python\Python312\Lib\site-packages\sqlalchemy\engine\default.py", line 683, in do_rollback
    dbapi_connection.rollback()
sqlite3.ProgrammingError: SQLite objects created in a thread can only be used in that same thread. The object was created in thread id 45496 and this is thread id 45380.

During handling of the above exception, another exception occurred:

Traceback (most recent call last):
  File "C:\Users\tiago\AppData\Local\Programs\Python\Python312\Lib\site-packages\sqlalchemy\pool\base.py", line 255, in _close_connection
    self._dialect.do_terminate(connection)
  File "C:\Users\tiago\AppData\Local\Programs\Python\Python312\Lib\site-packages\sqlalchemy\engine\default.py", line 689, in do_terminate
    self.do_close(dbapi_connection)
  File "C:\Users\tiago\AppData\Local\Programs\Python\Python312\Lib\site-packages\sqlalchemy\engine\default.py", line 692, in do_close
    dbapi_connection.close()
sqlite3.ProgrammingError: SQLite objects created in a thread can only be used in that same thread. The object was created in thread id 45496 and this is thread id 45380.
ERROR:sqlalchemy.pool.impl.NullPool:Exception during reset or similar
Traceback (most recent call last):
  File "C:\Users\tiago\AppData\Local\Programs\Python\Python312\Lib\site-packages\sqlalchemy\pool\base.py", line 753, in _finalize_fairy
    fairy._reset(pool)
  File "C:\Users\tiago\AppData\Local\Programs\Python\Python312\Lib\site-packages\sqlalchemy\pool\base.py", line 1004, in _reset
    pool._dialect.do_rollback(self)
  File "C:\Users\tiago\AppData\Local\Programs\Python\Python312\Lib\site-packages\sqlalchemy\engine\default.py", line 683, in do_rollback
    dbapi_connection.rollback()
sqlite3.ProgrammingError: SQLite objects created in a thread can only be used in that same thread. The object was created in thread id 1476 and this is thread id 45380.
ERROR:sqlalchemy.pool.impl.NullPool:Exception closing connection <sqlite3.Connection object at 0x0000021CD9F01C60>
Traceback (most recent call last):
  File "C:\Users\tiago\AppData\Local\Programs\Python\Python312\Lib\site-packages\sqlalchemy\pool\base.py", line 753, in _finalize_fairy
    fairy._reset(pool)
  File "C:\Users\tiago\AppData\Local\Programs\Python\Python312\Lib\site-packages\sqlalchemy\pool\base.py", line 1004, in _reset
    pool._dialect.do_rollback(self)
  File "C:\Users\tiago\AppData\Local\Programs\Python\Python312\Lib\site-packages\sqlalchemy\engine\default.py", line 683, in do_rollback
    dbapi_connection.rollback()
sqlite3.ProgrammingError: SQLite objects created in a thread can only be used in that same thread. The object was created in thread id 1476 and this is thread id 45380.

During handling of the above exception, another exception occurred:

Traceback (most recent call last):
  File "C:\Users\tiago\AppData\Local\Programs\Python\Python312\Lib\site-packages\sqlalchemy\pool\base.py", line 255, in _close_connection
    self._dialect.do_terminate(connection)
  File "C:\Users\tiago\AppData\Local\Programs\Python\Python312\Lib\site-packages\sqlalchemy\engine\default.py", line 689, in do_terminate
    self.do_close(dbapi_connection)
  File "C:\Users\tiago\AppData\Local\Programs\Python\Python312\Lib\site-packages\sqlalchemy\engine\default.py", line 692, in do_close
    dbapi_connection.close()
sqlite3.ProgrammingError: SQLite objects created in a thread can only be used in that same thread. The object was created in thread id 1476 and this is thread id 45380.
ERROR:sqlalchemy.pool.impl.NullPool:Exception during reset or similar
Traceback (most recent call last):
  File "C:\Users\tiago\AppData\Local\Programs\Python\Python312\Lib\site-packages\sqlalchemy\pool\base.py", line 753, in _finalize_fairy
    fairy._reset(pool)
  File "C:\Users\tiago\AppData\Local\Programs\Python\Python312\Lib\site-packages\sqlalchemy\pool\base.py", line 1004, in _reset
    pool._dialect.do_rollback(self)
  File "C:\Users\tiago\AppData\Local\Programs\Python\Python312\Lib\site-packages\sqlalchemy\engine\default.py", line 683, in do_rollback
    dbapi_connection.rollback()
sqlite3.ProgrammingError: SQLite objects created in a thread can only be used in that same thread. The object was created in thread id 47944 and this is thread id 45380.
ERROR:sqlalchemy.pool.impl.NullPool:Exception closing connection <sqlite3.Connection object at 0x0000021CD9F00C70>
Traceback (most recent call last):
  File "C:\Users\tiago\AppData\Local\Programs\Python\Python312\Lib\site-packages\sqlalchemy\pool\base.py", line 753, in _finalize_fairy
    fairy._reset(pool)
  File "C:\Users\tiago\AppData\Local\Programs\Python\Python312\Lib\site-packages\sqlalchemy\pool\base.py", line 1004, in _reset
    pool._dialect.do_rollback(self)
  File "C:\Users\tiago\AppData\Local\Programs\Python\Python312\Lib\site-packages\sqlalchemy\engine\default.py", line 683, in do_rollback
    dbapi_connection.rollback()
sqlite3.ProgrammingError: SQLite objects created in a thread can only be used in that same thread. The object was created in thread id 47944 and this is thread id 45380.

During handling of the above exception, another exception occurred:

Traceback (most recent call last):
  File "C:\Users\tiago\AppData\Local\Programs\Python\Python312\Lib\site-packages\sqlalchemy\pool\base.py", line 255, in _close_connection
    self._dialect.do_terminate(connection)
  File "C:\Users\tiago\AppData\Local\Programs\Python\Python312\Lib\site-packages\sqlalchemy\engine\default.py", line 689, in do_terminate
    self.do_close(dbapi_connection)
  File "C:\Users\tiago\AppData\Local\Programs\Python\Python312\Lib\site-packages\sqlalchemy\engine\default.py", line 692, in do_close
    dbapi_connection.close()
sqlite3.ProgrammingError: SQLite objects created in a thread can only be used in that same thread. The object was created in thread id 47944 and this is thread id 45380.
ERROR:sqlalchemy.pool.impl.NullPool:Exception during reset or similar
Traceback (most recent call last):
  File "C:\Users\tiago\AppData\Local\Programs\Python\Python312\Lib\site-packages\sqlalchemy\pool\base.py", line 753, in _finalize_fairy
    fairy._reset(pool)
  File "C:\Users\tiago\AppData\Local\Programs\Python\Python312\Lib\site-packages\sqlalchemy\pool\base.py", line 1004, in _reset
    pool._dialect.do_rollback(self)
  File "C:\Users\tiago\AppData\Local\Programs\Python\Python312\Lib\site-packages\sqlalchemy\engine\default.py", line 683, in do_rollback
    dbapi_connection.rollback()
sqlite3.ProgrammingError: SQLite objects created in a thread can only be used in that same thread. The object was created in thread id 26760 and this is thread id 45380.
ERROR:sqlalchemy.pool.impl.NullPool:Exception closing connection <sqlite3.Connection object at 0x0000021CD9F03010>
Traceback (most recent call last):
  File "C:\Users\tiago\AppData\Local\Programs\Python\Python312\Lib\site-packages\sqlalchemy\pool\base.py", line 753, in _finalize_fairy
    fairy._reset(pool)
  File "C:\Users\tiago\AppData\Local\Programs\Python\Python312\Lib\site-packages\sqlalchemy\pool\base.py", line 1004, in _reset
    pool._dialect.do_rollback(self)
  File "C:\Users\tiago\AppData\Local\Programs\Python\Python312\Lib\site-packages\sqlalchemy\engine\default.py", line 683, in do_rollback
    dbapi_connection.rollback()
sqlite3.ProgrammingError: SQLite objects created in a thread can only be used in that same thread. The object was created in thread id 26760 and this is thread id 45380.

During handling of the above exception, another exception occurred:

Traceback (most recent call last):
  File "C:\Users\tiago\AppData\Local\Programs\Python\Python312\Lib\site-packages\sqlalchemy\pool\base.py", line 255, in _close_connection
    self._dialect.do_terminate(connection)
  File "C:\Users\tiago\AppData\Local\Programs\Python\Python312\Lib\site-packages\sqlalchemy\engine\default.py", line 689, in do_terminate
    self.do_close(dbapi_connection)
  File "C:\Users\tiago\AppData\Local\Programs\Python\Python312\Lib\site-packages\sqlalchemy\engine\default.py", line 692, in do_close
    dbapi_connection.close()
sqlite3.ProgrammingError: SQLite objects created in a thread can only be used in that same thread. The object was created in thread id 26760 and this is thread id 45380.
ERROR:sqlalchemy.pool.impl.NullPool:Exception during reset or similar
Traceback (most recent call last):
  File "C:\Users\tiago\AppData\Local\Programs\Python\Python312\Lib\site-packages\sqlalchemy\pool\base.py", line 753, in _finalize_fairy
    fairy._reset(pool)
  File "C:\Users\tiago\AppData\Local\Programs\Python\Python312\Lib\site-packages\sqlalchemy\pool\base.py", line 1004, in _reset
    pool._dialect.do_rollback(self)
  File "C:\Users\tiago\AppData\Local\Programs\Python\Python312\Lib\site-packages\sqlalchemy\engine\default.py", line 683, in do_rollback
    dbapi_connection.rollback()
sqlite3.ProgrammingError: SQLite objects created in a thread can only be used in that same thread. The object was created in thread id 21932 and this is thread id 45380.
ERROR:sqlalchemy.pool.impl.NullPool:Exception closing connection <sqlite3.Connection object at 0x0000021CD9F01990>
Traceback (most recent call last):
  File "C:\Users\tiago\AppData\Local\Programs\Python\Python312\Lib\site-packages\sqlalchemy\pool\base.py", line 753, in _finalize_fairy
    fairy._reset(pool)
  File "C:\Users\tiago\AppData\Local\Programs\Python\Python312\Lib\site-packages\sqlalchemy\pool\base.py", line 1004, in _reset
    pool._dialect.do_rollback(self)
  File "C:\Users\tiago\AppData\Local\Programs\Python\Python312\Lib\site-packages\sqlalchemy\engine\default.py", line 683, in do_rollback
    dbapi_connection.rollback()
sqlite3.ProgrammingError: SQLite objects created in a thread can only be used in that same thread. The object was created in thread id 21932 and this is thread id 45380.

During handling of the above exception, another exception occurred:

Traceback (most recent call last):
  File "C:\Users\tiago\AppData\Local\Programs\Python\Python312\Lib\site-packages\sqlalchemy\pool\base.py", line 255, in _close_connection
    self._dialect.do_terminate(connection)
  File "C:\Users\tiago\AppData\Local\Programs\Python\Python312\Lib\site-packages\sqlalchemy\engine\default.py", line 689, in do_terminate
    self.do_close(dbapi_connection)
  File "C:\Users\tiago\AppData\Local\Programs\Python\Python312\Lib\site-packages\sqlalchemy\engine\default.py", line 692, in do_close
    dbapi_connection.close()
sqlite3.ProgrammingError: SQLite objects created in a thread can only be used in that same thread. The object was created in thread id 21932 and this is thread id 45380.
ERROR:sqlalchemy.pool.impl.NullPool:Exception during reset or similar
Traceback (most recent call last):
  File "C:\Users\tiago\AppData\Local\Programs\Python\Python312\Lib\site-packages\sqlalchemy\pool\base.py", line 753, in _finalize_fairy
    fairy._reset(pool)
  File "C:\Users\tiago\AppData\Local\Programs\Python\Python312\Lib\site-packages\sqlalchemy\pool\base.py", line 1004, in _reset
    pool._dialect.do_rollback(self)
  File "C:\Users\tiago\AppData\Local\Programs\Python\Python312\Lib\site-packages\sqlalchemy\engine\default.py", line 683, in do_rollback
    dbapi_connection.rollback()
sqlite3.ProgrammingError: SQLite objects created in a thread can only be used in that same thread. The object was created in thread id 4544 and this is thread id 45380.
ERROR:sqlalchemy.pool.impl.NullPool:Exception closing connection <sqlite3.Connection object at 0x0000021CD9F02020>
Traceback (most recent call last):
  File "C:\Users\tiago\AppData\Local\Programs\Python\Python312\Lib\site-packages\sqlalchemy\pool\base.py", line 753, in _finalize_fairy
    fairy._reset(pool)
  File "C:\Users\tiago\AppData\Local\Programs\Python\Python312\Lib\site-packages\sqlalchemy\pool\base.py", line 1004, in _reset
    pool._dialect.do_rollback(self)
  File "C:\Users\tiago\AppData\Local\Programs\Python\Python312\Lib\site-packages\sqlalchemy\engine\default.py", line 683, in do_rollback
    dbapi_connection.rollback()
sqlite3.ProgrammingError: SQLite objects created in a thread can only be used in that same thread. The object was created in thread id 4544 and this is thread id 45380.

During handling of the above exception, another exception occurred:

Traceback (most recent call last):
  File "C:\Users\tiago\AppData\Local\Programs\Python\Python312\Lib\site-packages\sqlalchemy\pool\base.py", line 255, in _close_connection
    self._dialect.do_terminate(connection)
  File "C:\Users\tiago\AppData\Local\Programs\Python\Python312\Lib\site-packages\sqlalchemy\engine\default.py", line 689, in do_terminate
    self.do_close(dbapi_connection)
  File "C:\Users\tiago\AppData\Local\Programs\Python\Python312\Lib\site-packages\sqlalchemy\engine\default.py", line 692, in do_close
    dbapi_connection.close()
sqlite3.ProgrammingError: SQLite objects created in a thread can only be used in that same thread. The object was created in thread id 4544 and this is thread id 45380.
ERROR:sqlalchemy.pool.impl.NullPool:Exception during reset or similar
Traceback (most recent call last):
  File "C:\Users\tiago\AppData\Local\Programs\Python\Python312\Lib\site-packages\sqlalchemy\pool\base.py", line 753, in _finalize_fairy
    fairy._reset(pool)
  File "C:\Users\tiago\AppData\Local\Programs\Python\Python312\Lib\site-packages\sqlalchemy\pool\base.py", line 1004, in _reset
    pool._dialect.do_rollback(self)
  File "C:\Users\tiago\AppData\Local\Programs\Python\Python312\Lib\site-packages\sqlalchemy\engine\default.py", line 683, in do_rollback
    dbapi_connection.rollback()
sqlite3.ProgrammingError: SQLite objects created in a thread can only be used in that same thread. The object was created in thread id 4076 and this is thread id 45380.
ERROR:sqlalchemy.pool.impl.NullPool:Exception closing connection <sqlite3.Connection object at 0x0000021CD9F033D0>
Traceback (most recent call last):
  File "C:\Users\tiago\AppData\Local\Programs\Python\Python312\Lib\site-packages\sqlalchemy\pool\base.py", line 753, in _finalize_fairy
    fairy._reset(pool)
  File "C:\Users\tiago\AppData\Local\Programs\Python\Python312\Lib\site-packages\sqlalchemy\pool\base.py", line 1004, in _reset
    pool._dialect.do_rollback(self)
  File "C:\Users\tiago\AppData\Local\Programs\Python\Python312\Lib\site-packages\sqlalchemy\engine\default.py", line 683, in do_rollback
    dbapi_connection.rollback()
sqlite3.ProgrammingError: SQLite objects created in a thread can only be used in that same thread. The object was created in thread id 4076 and this is thread id 45380.

During handling of the above exception, another exception occurred:

Traceback (most recent call last):
  File "C:\Users\tiago\AppData\Local\Programs\Python\Python312\Lib\site-packages\sqlalchemy\pool\base.py", line 255, in _close_connection
    self._dialect.do_terminate(connection)
  File "C:\Users\tiago\AppData\Local\Programs\Python\Python312\Lib\site-packages\sqlalchemy\engine\default.py", line 689, in do_terminate
    self.do_close(dbapi_connection)
  File "C:\Users\tiago\AppData\Local\Programs\Python\Python312\Lib\site-packages\sqlalchemy\engine\default.py", line 692, in do_close
    dbapi_connection.close()
sqlite3.ProgrammingError: SQLite objects created in a thread can only be used in that same thread. The object was created in thread id 4076 and this is thread id 45380.
INFO:werkzeug:[31m[1mWARNING: This is a development server. Do not use it in a production deployment. Use a production WSGI server instead.[0m
 * Running on http://127.0.0.1:5000
INFO:werkzeug:[33mPress CTRL+C to quit[0m
DEBUG:root:Consulta todos os eventos
INFO:werkzeug:127.0.0.1 - - [17/Apr/2024 00:02:00] "GET /evento HTTP/1.1" 200 -
DEBUG:root:Adicionando evento de nome: '1o encontro de teste'
DEBUG:root:Adicionado evento de nome: '1o encontro de teste'
INFO:werkzeug:127.0.0.1 - - [17/Apr/2024 00:02:28] "POST /evento HTTP/1.1" 200 -
DEBUG:root:Consulta todos os eventos
INFO:werkzeug:127.0.0.1 - - [17/Apr/2024 00:02:29] "GET /evento HTTP/1.1" 200 -
DEBUG:root:Consulta todos os responsavels
ERROR:sqlalchemy.pool.impl.NullPool:Exception during reset or similar
Traceback (most recent call last):
  File "C:\Users\tiago\AppData\Local\Programs\Python\Python312\Lib\site-packages\sqlalchemy\pool\base.py", line 753, in _finalize_fairy
    fairy._reset(pool)
  File "C:\Users\tiago\AppData\Local\Programs\Python\Python312\Lib\site-packages\sqlalchemy\pool\base.py", line 1004, in _reset
    pool._dialect.do_rollback(self)
  File "C:\Users\tiago\AppData\Local\Programs\Python\Python312\Lib\site-packages\sqlalchemy\engine\default.py", line 683, in do_rollback
    dbapi_connection.rollback()
sqlite3.ProgrammingError: SQLite objects created in a thread can only be used in that same thread. The object was created in thread id 45000 and this is thread id 47372.
ERROR:sqlalchemy.pool.impl.NullPool:Exception closing connection <sqlite3.Connection object at 0x0000015FBDB91F30>
Traceback (most recent call last):
  File "C:\Users\tiago\AppData\Local\Programs\Python\Python312\Lib\site-packages\sqlalchemy\pool\base.py", line 753, in _finalize_fairy
    fairy._reset(pool)
  File "C:\Users\tiago\AppData\Local\Programs\Python\Python312\Lib\site-packages\sqlalchemy\pool\base.py", line 1004, in _reset
    pool._dialect.do_rollback(self)
  File "C:\Users\tiago\AppData\Local\Programs\Python\Python312\Lib\site-packages\sqlalchemy\engine\default.py", line 683, in do_rollback
    dbapi_connection.rollback()
sqlite3.ProgrammingError: SQLite objects created in a thread can only be used in that same thread. The object was created in thread id 45000 and this is thread id 47372.

During handling of the above exception, another exception occurred:

Traceback (most recent call last):
  File "C:\Users\tiago\AppData\Local\Programs\Python\Python312\Lib\site-packages\sqlalchemy\pool\base.py", line 255, in _close_connection
    self._dialect.do_terminate(connection)
  File "C:\Users\tiago\AppData\Local\Programs\Python\Python312\Lib\site-packages\sqlalchemy\engine\default.py", line 689, in do_terminate
    self.do_close(dbapi_connection)
  File "C:\Users\tiago\AppData\Local\Programs\Python\Python312\Lib\site-packages\sqlalchemy\engine\default.py", line 692, in do_close
    dbapi_connection.close()
sqlite3.ProgrammingError: SQLite objects created in a thread can only be used in that same thread. The object was created in thread id 45000 and this is thread id 47372.
INFO:werkzeug:127.0.0.1 - - [17/Apr/2024 00:02:32] "GET /responsavel?eventoid=1 HTTP/1.1" 200 -
DEBUG:root:Consulta todas as salas
DEBUG:root:Consulta todos os centrodeinteresses
INFO:werkzeug:127.0.0.1 - - [17/Apr/2024 00:02:32] "GET /sala HTTP/1.1" 200 -
INFO:werkzeug:127.0.0.1 - - [17/Apr/2024 00:02:32] "GET /centrodeinteresse?eventoId=1 HTTP/1.1" 200 -
INFO:werkzeug:[31m[1mWARNING: This is a development server. Do not use it in a production deployment. Use a production WSGI server instead.[0m
 * Running on http://127.0.0.1:5000
INFO:werkzeug:[33mPress CTRL+C to quit[0m
INFO:werkzeug:127.0.0.1 - - [17/Apr/2024 00:05:24] "[36mGET /openapi/static/css/swagger-ui.css HTTP/1.1[0m" 304 -
INFO:werkzeug:127.0.0.1 - - [17/Apr/2024 00:05:24] "[36mGET /openapi/static/js/swagger-ui-bundle.js HTTP/1.1[0m" 304 -
INFO:werkzeug:127.0.0.1 - - [17/Apr/2024 00:05:24] "[36mGET /openapi/static/js/swagger-ui-standalone-preset.js HTTP/1.1[0m" 304 -
INFO:werkzeug:127.0.0.1 - - [17/Apr/2024 00:05:25] "GET /openapi/openapi.json HTTP/1.1" 200 -
DEBUG:root:Consulta todos os eventos
INFO:werkzeug:127.0.0.1 - - [17/Apr/2024 00:05:42] "GET /evento HTTP/1.1" 200 -
DEBUG:root:Consulta todos os eventos
INFO:werkzeug:127.0.0.1 - - [17/Apr/2024 00:05:43] "GET /evento HTTP/1.1" 200 -
DEBUG:root:Consulta todos os eventos
DEBUG:root:Consulta todos os responsavels
ERROR:sqlalchemy.pool.impl.NullPool:Exception during reset or similar
Traceback (most recent call last):
  File "C:\Users\tiago\AppData\Local\Programs\Python\Python312\Lib\site-packages\sqlalchemy\pool\base.py", line 753, in _finalize_fairy
    fairy._reset(pool)
  File "C:\Users\tiago\AppData\Local\Programs\Python\Python312\Lib\site-packages\sqlalchemy\pool\base.py", line 1004, in _reset
    pool._dialect.do_rollback(self)
  File "C:\Users\tiago\AppData\Local\Programs\Python\Python312\Lib\site-packages\sqlalchemy\engine\default.py", line 683, in do_rollback
    dbapi_connection.rollback()
sqlite3.ProgrammingError: SQLite objects created in a thread can only be used in that same thread. The object was created in thread id 49084 and this is thread id 36680.
DEBUG:root:Consulta todas as salas
INFO:werkzeug:127.0.0.1 - - [17/Apr/2024 00:05:47] "GET /eventoporid?id=1 HTTP/1.1" 200 -
INFO:werkzeug:127.0.0.1 - - [17/Apr/2024 00:05:47] "GET /responsavel?eventoid=1 HTTP/1.1" 200 -
ERROR:sqlalchemy.pool.impl.NullPool:Exception closing connection <sqlite3.Connection object at 0x0000015FBDB91E40>
Traceback (most recent call last):
  File "C:\Users\tiago\AppData\Local\Programs\Python\Python312\Lib\site-packages\sqlalchemy\pool\base.py", line 753, in _finalize_fairy
    fairy._reset(pool)
  File "C:\Users\tiago\AppData\Local\Programs\Python\Python312\Lib\site-packages\sqlalchemy\pool\base.py", line 1004, in _reset
    pool._dialect.do_rollback(self)
  File "C:\Users\tiago\AppData\Local\Programs\Python\Python312\Lib\site-packages\sqlalchemy\engine\default.py", line 683, in do_rollback
    dbapi_connection.rollback()
sqlite3.ProgrammingError: SQLite objects created in a thread can only be used in that same thread. The object was created in thread id 49084 and this is thread id 36680.

During handling of the above exception, another exception occurred:

Traceback (most recent call last):
  File "C:\Users\tiago\AppData\Local\Programs\Python\Python312\Lib\site-packages\sqlalchemy\pool\base.py", line 255, in _close_connection
    self._dialect.do_terminate(connection)
  File "C:\Users\tiago\AppData\Local\Programs\Python\Python312\Lib\site-packages\sqlalchemy\engine\default.py", line 689, in do_terminate
    self.do_close(dbapi_connection)
  File "C:\Users\tiago\AppData\Local\Programs\Python\Python312\Lib\site-packages\sqlalchemy\engine\default.py", line 692, in do_close
    dbapi_connection.close()
sqlite3.ProgrammingError: SQLite objects created in a thread can only be used in that same thread. The object was created in thread id 49084 and this is thread id 36680.
DEBUG:root:Consulta todos os centrodeinteresses
ERROR:sqlalchemy.pool.impl.NullPool:Exception during reset or similar
Traceback (most recent call last):
  File "C:\Users\tiago\AppData\Local\Programs\Python\Python312\Lib\site-packages\sqlalchemy\pool\base.py", line 753, in _finalize_fairy
    fairy._reset(pool)
  File "C:\Users\tiago\AppData\Local\Programs\Python\Python312\Lib\site-packages\sqlalchemy\pool\base.py", line 1004, in _reset
    pool._dialect.do_rollback(self)
  File "C:\Users\tiago\AppData\Local\Programs\Python\Python312\Lib\site-packages\sqlalchemy\engine\default.py", line 683, in do_rollback
    dbapi_connection.rollback()
sqlite3.ProgrammingError: SQLite objects created in a thread can only be used in that same thread. The object was created in thread id 49876 and this is thread id 36680.
ERROR:sqlalchemy.pool.impl.NullPool:Exception closing connection <sqlite3.Connection object at 0x0000015FBDB922F0>
Traceback (most recent call last):
  File "C:\Users\tiago\AppData\Local\Programs\Python\Python312\Lib\site-packages\sqlalchemy\pool\base.py", line 753, in _finalize_fairy
    fairy._reset(pool)
  File "C:\Users\tiago\AppData\Local\Programs\Python\Python312\Lib\site-packages\sqlalchemy\pool\base.py", line 1004, in _reset
    pool._dialect.do_rollback(self)
  File "C:\Users\tiago\AppData\Local\Programs\Python\Python312\Lib\site-packages\sqlalchemy\engine\default.py", line 683, in do_rollback
    dbapi_connection.rollback()
sqlite3.ProgrammingError: SQLite objects created in a thread can only be used in that same thread. The object was created in thread id 49876 and this is thread id 36680.

During handling of the above exception, another exception occurred:

Traceback (most recent call last):
  File "C:\Users\tiago\AppData\Local\Programs\Python\Python312\Lib\site-packages\sqlalchemy\pool\base.py", line 255, in _close_connection
    self._dialect.do_terminate(connection)
  File "C:\Users\tiago\AppData\Local\Programs\Python\Python312\Lib\site-packages\sqlalchemy\engine\default.py", line 689, in do_terminate
    self.do_close(dbapi_connection)
  File "C:\Users\tiago\AppData\Local\Programs\Python\Python312\Lib\site-packages\sqlalchemy\engine\default.py", line 692, in do_close
    dbapi_connection.close()
sqlite3.ProgrammingError: SQLite objects created in a thread can only be used in that same thread. The object was created in thread id 49876 and this is thread id 36680.
INFO:werkzeug:127.0.0.1 - - [17/Apr/2024 00:05:47] "GET /sala HTTP/1.1" 200 -
INFO:werkzeug:127.0.0.1 - - [17/Apr/2024 00:05:47] "GET /centrodeinteresse?eventoId=1 HTTP/1.1" 200 -
DEBUG:root:Consulta todos os participantes
INFO:werkzeug:127.0.0.1 - - [17/Apr/2024 00:05:47] "GET /participante?eventoId=1 HTTP/1.1" 200 -
DEBUG:root:Consulta todos os responsavels
ERROR:sqlalchemy.pool.impl.NullPool:Exception during reset or similar
Traceback (most recent call last):
  File "C:\Users\tiago\AppData\Local\Programs\Python\Python312\Lib\site-packages\sqlalchemy\pool\base.py", line 753, in _finalize_fairy
    fairy._reset(pool)
  File "C:\Users\tiago\AppData\Local\Programs\Python\Python312\Lib\site-packages\sqlalchemy\pool\base.py", line 1004, in _reset
    pool._dialect.do_rollback(self)
  File "C:\Users\tiago\AppData\Local\Programs\Python\Python312\Lib\site-packages\sqlalchemy\engine\default.py", line 683, in do_rollback
    dbapi_connection.rollback()
sqlite3.ProgrammingError: SQLite objects created in a thread can only be used in that same thread. The object was created in thread id 50716 and this is thread id 43804.
ERROR:sqlalchemy.pool.impl.NullPool:Exception closing connection <sqlite3.Connection object at 0x0000015FBDB925C0>
Traceback (most recent call last):
  File "C:\Users\tiago\AppData\Local\Programs\Python\Python312\Lib\site-packages\sqlalchemy\pool\base.py", line 753, in _finalize_fairy
    fairy._reset(pool)
  File "C:\Users\tiago\AppData\Local\Programs\Python\Python312\Lib\site-packages\sqlalchemy\pool\base.py", line 1004, in _reset
    pool._dialect.do_rollback(self)
  File "C:\Users\tiago\AppData\Local\Programs\Python\Python312\Lib\site-packages\sqlalchemy\engine\default.py", line 683, in do_rollback
    dbapi_connection.rollback()
sqlite3.ProgrammingError: SQLite objects created in a thread can only be used in that same thread. The object was created in thread id 50716 and this is thread id 43804.

During handling of the above exception, another exception occurred:

Traceback (most recent call last):
  File "C:\Users\tiago\AppData\Local\Programs\Python\Python312\Lib\site-packages\sqlalchemy\pool\base.py", line 255, in _close_connection
    self._dialect.do_terminate(connection)
  File "C:\Users\tiago\AppData\Local\Programs\Python\Python312\Lib\site-packages\sqlalchemy\engine\default.py", line 689, in do_terminate
    self.do_close(dbapi_connection)
  File "C:\Users\tiago\AppData\Local\Programs\Python\Python312\Lib\site-packages\sqlalchemy\engine\default.py", line 692, in do_close
    dbapi_connection.close()
sqlite3.ProgrammingError: SQLite objects created in a thread can only be used in that same thread. The object was created in thread id 50716 and this is thread id 43804.
ERROR:sqlalchemy.pool.impl.NullPool:Exception during reset or similar
Traceback (most recent call last):
  File "C:\Users\tiago\AppData\Local\Programs\Python\Python312\Lib\site-packages\sqlalchemy\pool\base.py", line 753, in _finalize_fairy
    fairy._reset(pool)
  File "C:\Users\tiago\AppData\Local\Programs\Python\Python312\Lib\site-packages\sqlalchemy\pool\base.py", line 1004, in _reset
    pool._dialect.do_rollback(self)
  File "C:\Users\tiago\AppData\Local\Programs\Python\Python312\Lib\site-packages\sqlalchemy\engine\default.py", line 683, in do_rollback
    dbapi_connection.rollback()
sqlite3.ProgrammingError: SQLite objects created in a thread can only be used in that same thread. The object was created in thread id 43776 and this is thread id 43804.
ERROR:sqlalchemy.pool.impl.NullPool:Exception closing connection <sqlite3.Connection object at 0x0000015FBDB91300>
Traceback (most recent call last):
  File "C:\Users\tiago\AppData\Local\Programs\Python\Python312\Lib\site-packages\sqlalchemy\pool\base.py", line 753, in _finalize_fairy
    fairy._reset(pool)
  File "C:\Users\tiago\AppData\Local\Programs\Python\Python312\Lib\site-packages\sqlalchemy\pool\base.py", line 1004, in _reset
    pool._dialect.do_rollback(self)
  File "C:\Users\tiago\AppData\Local\Programs\Python\Python312\Lib\site-packages\sqlalchemy\engine\default.py", line 683, in do_rollback
    dbapi_connection.rollback()
sqlite3.ProgrammingError: SQLite objects created in a thread can only be used in that same thread. The object was created in thread id 43776 and this is thread id 43804.

During handling of the above exception, another exception occurred:

Traceback (most recent call last):
  File "C:\Users\tiago\AppData\Local\Programs\Python\Python312\Lib\site-packages\sqlalchemy\pool\base.py", line 255, in _close_connection
    self._dialect.do_terminate(connection)
  File "C:\Users\tiago\AppData\Local\Programs\Python\Python312\Lib\site-packages\sqlalchemy\engine\default.py", line 689, in do_terminate
    self.do_close(dbapi_connection)
  File "C:\Users\tiago\AppData\Local\Programs\Python\Python312\Lib\site-packages\sqlalchemy\engine\default.py", line 692, in do_close
    dbapi_connection.close()
sqlite3.ProgrammingError: SQLite objects created in a thread can only be used in that same thread. The object was created in thread id 43776 and this is thread id 43804.
ERROR:sqlalchemy.pool.impl.NullPool:Exception during reset or similar
Traceback (most recent call last):
  File "C:\Users\tiago\AppData\Local\Programs\Python\Python312\Lib\site-packages\sqlalchemy\pool\base.py", line 753, in _finalize_fairy
    fairy._reset(pool)
  File "C:\Users\tiago\AppData\Local\Programs\Python\Python312\Lib\site-packages\sqlalchemy\pool\base.py", line 1004, in _reset
    pool._dialect.do_rollback(self)
  File "C:\Users\tiago\AppData\Local\Programs\Python\Python312\Lib\site-packages\sqlalchemy\engine\default.py", line 683, in do_rollback
    dbapi_connection.rollback()
sqlite3.ProgrammingError: SQLite objects created in a thread can only be used in that same thread. The object was created in thread id 36680 and this is thread id 43804.
ERROR:sqlalchemy.pool.impl.NullPool:Exception closing connection <sqlite3.Connection object at 0x0000015FBDA165C0>
Traceback (most recent call last):
  File "C:\Users\tiago\AppData\Local\Programs\Python\Python312\Lib\site-packages\sqlalchemy\pool\base.py", line 753, in _finalize_fairy
    fairy._reset(pool)
  File "C:\Users\tiago\AppData\Local\Programs\Python\Python312\Lib\site-packages\sqlalchemy\pool\base.py", line 1004, in _reset
    pool._dialect.do_rollback(self)
  File "C:\Users\tiago\AppData\Local\Programs\Python\Python312\Lib\site-packages\sqlalchemy\engine\default.py", line 683, in do_rollback
    dbapi_connection.rollback()
sqlite3.ProgrammingError: SQLite objects created in a thread can only be used in that same thread. The object was created in thread id 36680 and this is thread id 43804.

During handling of the above exception, another exception occurred:

Traceback (most recent call last):
  File "C:\Users\tiago\AppData\Local\Programs\Python\Python312\Lib\site-packages\sqlalchemy\pool\base.py", line 255, in _close_connection
    self._dialect.do_terminate(connection)
  File "C:\Users\tiago\AppData\Local\Programs\Python\Python312\Lib\site-packages\sqlalchemy\engine\default.py", line 689, in do_terminate
    self.do_close(dbapi_connection)
  File "C:\Users\tiago\AppData\Local\Programs\Python\Python312\Lib\site-packages\sqlalchemy\engine\default.py", line 692, in do_close
    dbapi_connection.close()
sqlite3.ProgrammingError: SQLite objects created in a thread can only be used in that same thread. The object was created in thread id 36680 and this is thread id 43804.
INFO:werkzeug:127.0.0.1 - - [17/Apr/2024 00:05:47] "GET /responsavel?eventoid=1 HTTP/1.1" 200 -
DEBUG:root:Consulta todos os centrodeinteresses
INFO:werkzeug:127.0.0.1 - - [17/Apr/2024 00:05:47] "GET /centrodeinteresse?eventoId=1 HTTP/1.1" 200 -
DEBUG:root:Consulta todos os centrodeinteresses
INFO:werkzeug:127.0.0.1 - - [17/Apr/2024 00:05:47] "GET /centrodeinteresse?eventoId=1 HTTP/1.1" 200 -
